{
 "cells": [
  {
   "cell_type": "code",
   "execution_count": 1,
   "metadata": {},
   "outputs": [
    {
     "name": "stdout",
     "output_type": "stream",
     "text": [
      "\u001b[0m\n",
      "\u001b[34m\u001b[1m  You can now view your Streamlit app in your browser.\u001b[0m\n",
      "\u001b[0m\n",
      "\u001b[34m  Local URL: \u001b[0m\u001b[1mhttp://localhost:8501\u001b[0m\n",
      "\u001b[34m  Network URL: \u001b[0m\u001b[1mhttp://192.168.1.56:8501\u001b[0m\n",
      "\u001b[0m\n",
      "\n",
      "  \u001b[34m\u001b[1mA new version of Streamlit is available.\u001b[0m\n",
      "\n",
      "  See what's new at https://discuss.streamlit.io/c/announcements\n",
      "\n",
      "  Enter the following command to upgrade:\n",
      "  \u001b[34m$\u001b[0m \u001b[1mpip install streamlit --upgrade\u001b[0m\n",
      "\u001b[0m\n",
      "2024-09-07 12:41:25.833 Uncaught app exception\n",
      "Traceback (most recent call last):\n",
      "  File \"/Users/rmitta/opt/anaconda3/envs/zerotwo/lib/python3.10/site-packages/streamlit/runtime/scriptrunner/script_runner.py\", line 542, in _run_script\n",
      "    exec(code, module.__dict__)\n",
      "  File \"/Volumes/Fatboy/Indian Traffic/cities/streamlit/cities/pages/2 Model Results.py\", line 25, in <module>\n",
      "    metrics = pd.merge(metrics, r2_df[['city','r2_temporal','']], on='city', how='left')\n",
      "  File \"/Users/rmitta/opt/anaconda3/envs/zerotwo/lib/python3.10/site-packages/pandas/core/frame.py\", line 3511, in __getitem__\n",
      "    indexer = self.columns._get_indexer_strict(key, \"columns\")[1]\n",
      "  File \"/Users/rmitta/opt/anaconda3/envs/zerotwo/lib/python3.10/site-packages/pandas/core/indexes/base.py\", line 5796, in _get_indexer_strict\n",
      "    self._raise_if_missing(keyarr, indexer, axis_name)\n",
      "  File \"/Users/rmitta/opt/anaconda3/envs/zerotwo/lib/python3.10/site-packages/pandas/core/indexes/base.py\", line 5859, in _raise_if_missing\n",
      "    raise KeyError(f\"{not_found} not in index\")\n",
      "KeyError: \"[''] not in index\"\n",
      "2024-09-07 12:41:30.256 Uncaught app exception\n",
      "Traceback (most recent call last):\n",
      "  File \"/Users/rmitta/opt/anaconda3/envs/zerotwo/lib/python3.10/site-packages/streamlit/runtime/scriptrunner/script_runner.py\", line 542, in _run_script\n",
      "    exec(code, module.__dict__)\n",
      "  File \"/Volumes/Fatboy/Indian Traffic/cities/streamlit/cities/pages/2 Model Results.py\", line 25, in <module>\n",
      "    metrics = pd.merge(metrics, r2_df[['city','r2_temporal','r2']], on='city', how='left')\n",
      "  File \"/Users/rmitta/opt/anaconda3/envs/zerotwo/lib/python3.10/site-packages/pandas/core/frame.py\", line 3511, in __getitem__\n",
      "    indexer = self.columns._get_indexer_strict(key, \"columns\")[1]\n",
      "  File \"/Users/rmitta/opt/anaconda3/envs/zerotwo/lib/python3.10/site-packages/pandas/core/indexes/base.py\", line 5796, in _get_indexer_strict\n",
      "    self._raise_if_missing(keyarr, indexer, axis_name)\n",
      "  File \"/Users/rmitta/opt/anaconda3/envs/zerotwo/lib/python3.10/site-packages/pandas/core/indexes/base.py\", line 5859, in _raise_if_missing\n",
      "    raise KeyError(f\"{not_found} not in index\")\n",
      "KeyError: \"['r2'] not in index\"\n",
      "2024-09-07 12:43:29.041 Uncaught app exception\n",
      "Traceback (most recent call last):\n",
      "  File \"/Users/rmitta/opt/anaconda3/envs/zerotwo/lib/python3.10/site-packages/streamlit/runtime/scriptrunner/script_runner.py\", line 542, in _run_script\n",
      "    exec(code, module.__dict__)\n",
      "  File \"/Volumes/Fatboy/Indian Traffic/cities/streamlit/cities/pages/2 Model Results.py\", line 26, in <module>\n",
      "    metrics.drop(['RMSE','MAE',''], axis=1, inplace=True)\n",
      "  File \"/Users/rmitta/opt/anaconda3/envs/zerotwo/lib/python3.10/site-packages/pandas/util/_decorators.py\", line 311, in wrapper\n",
      "    return func(*args, **kwargs)\n",
      "  File \"/Users/rmitta/opt/anaconda3/envs/zerotwo/lib/python3.10/site-packages/pandas/core/frame.py\", line 4957, in drop\n",
      "    return super().drop(\n",
      "  File \"/Users/rmitta/opt/anaconda3/envs/zerotwo/lib/python3.10/site-packages/pandas/core/generic.py\", line 4267, in drop\n",
      "    obj = obj._drop_axis(labels, axis, level=level, errors=errors)\n",
      "  File \"/Users/rmitta/opt/anaconda3/envs/zerotwo/lib/python3.10/site-packages/pandas/core/generic.py\", line 4311, in _drop_axis\n",
      "    new_axis = axis.drop(labels, errors=errors)\n",
      "  File \"/Users/rmitta/opt/anaconda3/envs/zerotwo/lib/python3.10/site-packages/pandas/core/indexes/base.py\", line 6661, in drop\n",
      "    raise KeyError(f\"{list(labels[mask])} not found in axis\")\n",
      "KeyError: \"[''] not found in axis\"\n",
      "2024-09-07 12:44:34.247 Uncaught app exception\n",
      "Traceback (most recent call last):\n",
      "  File \"/Users/rmitta/opt/anaconda3/envs/zerotwo/lib/python3.10/site-packages/streamlit/runtime/scriptrunner/script_runner.py\", line 542, in _run_script\n",
      "    exec(code, module.__dict__)\n",
      "  File \"/Volumes/Fatboy/Indian Traffic/cities/streamlit/cities/pages/2 Model Results.py\", line 28, in <module>\n",
      "    metrics.columns = ['city', 'temporal (%)', 'spatial (%)', 'R2']\n",
      "  File \"/Users/rmitta/opt/anaconda3/envs/zerotwo/lib/python3.10/site-packages/pandas/core/generic.py\", line 5588, in __setattr__\n",
      "    return object.__setattr__(self, name, value)\n",
      "  File \"pandas/_libs/properties.pyx\", line 70, in pandas._libs.properties.AxisProperty.__set__\n",
      "  File \"/Users/rmitta/opt/anaconda3/envs/zerotwo/lib/python3.10/site-packages/pandas/core/generic.py\", line 769, in _set_axis\n",
      "    self._mgr.set_axis(axis, labels)\n",
      "  File \"/Users/rmitta/opt/anaconda3/envs/zerotwo/lib/python3.10/site-packages/pandas/core/internals/managers.py\", line 214, in set_axis\n",
      "    self._validate_set_axis(axis, new_labels)\n",
      "  File \"/Users/rmitta/opt/anaconda3/envs/zerotwo/lib/python3.10/site-packages/pandas/core/internals/base.py\", line 69, in _validate_set_axis\n",
      "    raise ValueError(\n",
      "ValueError: Length mismatch: Expected axis has 8 elements, new values have 4 elements\n",
      "2024-09-07 12:44:36.587 Uncaught app exception\n",
      "Traceback (most recent call last):\n",
      "  File \"/Users/rmitta/opt/anaconda3/envs/zerotwo/lib/python3.10/site-packages/streamlit/runtime/scriptrunner/script_runner.py\", line 542, in _run_script\n",
      "    exec(code, module.__dict__)\n",
      "  File \"/Volumes/Fatboy/Indian Traffic/cities/streamlit/cities/pages/2 Model Results.py\", line 28, in <module>\n",
      "    metrics.columns = ['city', '', 'spatial (%)', 'R2']\n",
      "  File \"/Users/rmitta/opt/anaconda3/envs/zerotwo/lib/python3.10/site-packages/pandas/core/generic.py\", line 5588, in __setattr__\n",
      "    return object.__setattr__(self, name, value)\n",
      "  File \"pandas/_libs/properties.pyx\", line 70, in pandas._libs.properties.AxisProperty.__set__\n",
      "  File \"/Users/rmitta/opt/anaconda3/envs/zerotwo/lib/python3.10/site-packages/pandas/core/generic.py\", line 769, in _set_axis\n",
      "    self._mgr.set_axis(axis, labels)\n",
      "  File \"/Users/rmitta/opt/anaconda3/envs/zerotwo/lib/python3.10/site-packages/pandas/core/internals/managers.py\", line 214, in set_axis\n",
      "    self._validate_set_axis(axis, new_labels)\n",
      "  File \"/Users/rmitta/opt/anaconda3/envs/zerotwo/lib/python3.10/site-packages/pandas/core/internals/base.py\", line 69, in _validate_set_axis\n",
      "    raise ValueError(\n",
      "ValueError: Length mismatch: Expected axis has 8 elements, new values have 4 elements\n",
      "2024-09-07 12:44:38.981 Uncaught app exception\n",
      "Traceback (most recent call last):\n",
      "  File \"/Users/rmitta/opt/anaconda3/envs/zerotwo/lib/python3.10/site-packages/streamlit/runtime/scriptrunner/script_runner.py\", line 542, in _run_script\n",
      "    exec(code, module.__dict__)\n",
      "  File \"/Volumes/Fatboy/Indian Traffic/cities/streamlit/cities/pages/2 Model Results.py\", line 28, in <module>\n",
      "    metrics.columns = ['city', '', 'spatial (%)', 'R2']\n",
      "  File \"/Users/rmitta/opt/anaconda3/envs/zerotwo/lib/python3.10/site-packages/pandas/core/generic.py\", line 5588, in __setattr__\n",
      "    return object.__setattr__(self, name, value)\n",
      "  File \"pandas/_libs/properties.pyx\", line 70, in pandas._libs.properties.AxisProperty.__set__\n",
      "  File \"/Users/rmitta/opt/anaconda3/envs/zerotwo/lib/python3.10/site-packages/pandas/core/generic.py\", line 769, in _set_axis\n",
      "    self._mgr.set_axis(axis, labels)\n",
      "  File \"/Users/rmitta/opt/anaconda3/envs/zerotwo/lib/python3.10/site-packages/pandas/core/internals/managers.py\", line 214, in set_axis\n",
      "    self._validate_set_axis(axis, new_labels)\n",
      "  File \"/Users/rmitta/opt/anaconda3/envs/zerotwo/lib/python3.10/site-packages/pandas/core/internals/base.py\", line 69, in _validate_set_axis\n",
      "    raise ValueError(\n",
      "ValueError: Length mismatch: Expected axis has 8 elements, new values have 4 elements\n",
      "2024-09-07 12:44:43.701 Uncaught app exception\n",
      "Traceback (most recent call last):\n",
      "  File \"/Users/rmitta/opt/anaconda3/envs/zerotwo/lib/python3.10/site-packages/streamlit/runtime/scriptrunner/script_runner.py\", line 542, in _run_script\n",
      "    exec(code, module.__dict__)\n",
      "  File \"/Volumes/Fatboy/Indian Traffic/cities/streamlit/cities/pages/2 Model Results.py\", line 31, in <module>\n",
      "    st.dataframe(metrics)\n",
      "  File \"/Users/rmitta/opt/anaconda3/envs/zerotwo/lib/python3.10/site-packages/streamlit/runtime/metrics_util.py\", line 397, in wrapped_func\n",
      "    result = non_optional_func(*args, **kwargs)\n",
      "  File \"/Users/rmitta/opt/anaconda3/envs/zerotwo/lib/python3.10/site-packages/streamlit/elements/arrow.py\", line 231, in dataframe\n",
      "    proto.data = type_util.data_frame_to_bytes(data_df)\n",
      "  File \"/Users/rmitta/opt/anaconda3/envs/zerotwo/lib/python3.10/site-packages/streamlit/type_util.py\", line 956, in data_frame_to_bytes\n",
      "    table = pa.Table.from_pandas(df)\n",
      "  File \"pyarrow/table.pxi\", line 3457, in pyarrow.lib.Table.from_pandas\n",
      "  File \"/Users/rmitta/opt/anaconda3/envs/zerotwo/lib/python3.10/site-packages/pyarrow/pandas_compat.py\", line 553, in dataframe_to_arrays\n",
      "    convert_fields) = _get_columns_to_convert(df, schema, preserve_index,\n",
      "  File \"/Users/rmitta/opt/anaconda3/envs/zerotwo/lib/python3.10/site-packages/pyarrow/pandas_compat.py\", line 337, in _get_columns_to_convert\n",
      "    raise ValueError(\n",
      "ValueError: Duplicate column names found: ['city', 'R2', 'RRMSE', 'year', 'temporal (%)', 'spatial (%)', 'temporal (%)', 'spatial (%)']\n",
      "2024-09-07 12:44:51.664 Uncaught app exception\n",
      "Traceback (most recent call last):\n",
      "  File \"/Users/rmitta/opt/anaconda3/envs/zerotwo/lib/python3.10/site-packages/streamlit/runtime/scriptrunner/script_runner.py\", line 542, in _run_script\n",
      "    exec(code, module.__dict__)\n",
      "  File \"/Volumes/Fatboy/Indian Traffic/cities/streamlit/cities/pages/2 Model Results.py\", line 31, in <module>\n",
      "    st.dataframe(metrics)\n",
      "  File \"/Users/rmitta/opt/anaconda3/envs/zerotwo/lib/python3.10/site-packages/streamlit/runtime/metrics_util.py\", line 397, in wrapped_func\n",
      "    result = non_optional_func(*args, **kwargs)\n",
      "  File \"/Users/rmitta/opt/anaconda3/envs/zerotwo/lib/python3.10/site-packages/streamlit/elements/arrow.py\", line 231, in dataframe\n",
      "    proto.data = type_util.data_frame_to_bytes(data_df)\n",
      "  File \"/Users/rmitta/opt/anaconda3/envs/zerotwo/lib/python3.10/site-packages/streamlit/type_util.py\", line 956, in data_frame_to_bytes\n",
      "    table = pa.Table.from_pandas(df)\n",
      "  File \"pyarrow/table.pxi\", line 3457, in pyarrow.lib.Table.from_pandas\n",
      "  File \"/Users/rmitta/opt/anaconda3/envs/zerotwo/lib/python3.10/site-packages/pyarrow/pandas_compat.py\", line 553, in dataframe_to_arrays\n",
      "    convert_fields) = _get_columns_to_convert(df, schema, preserve_index,\n",
      "  File \"/Users/rmitta/opt/anaconda3/envs/zerotwo/lib/python3.10/site-packages/pyarrow/pandas_compat.py\", line 337, in _get_columns_to_convert\n",
      "    raise ValueError(\n",
      "ValueError: Duplicate column names found: ['city', 'R2', 'RRMSE', 'year', 'temporal (%)', 'spatial (%)', '', 'spatial (%)']\n",
      "2024-09-07 12:44:52.704 Uncaught app exception\n",
      "Traceback (most recent call last):\n",
      "  File \"/Users/rmitta/opt/anaconda3/envs/zerotwo/lib/python3.10/site-packages/streamlit/runtime/scriptrunner/script_runner.py\", line 542, in _run_script\n",
      "    exec(code, module.__dict__)\n",
      "  File \"/Volumes/Fatboy/Indian Traffic/cities/streamlit/cities/pages/2 Model Results.py\", line 31, in <module>\n",
      "    st.dataframe(metrics)\n",
      "  File \"/Users/rmitta/opt/anaconda3/envs/zerotwo/lib/python3.10/site-packages/streamlit/runtime/metrics_util.py\", line 397, in wrapped_func\n",
      "    result = non_optional_func(*args, **kwargs)\n",
      "  File \"/Users/rmitta/opt/anaconda3/envs/zerotwo/lib/python3.10/site-packages/streamlit/elements/arrow.py\", line 231, in dataframe\n",
      "    proto.data = type_util.data_frame_to_bytes(data_df)\n",
      "  File \"/Users/rmitta/opt/anaconda3/envs/zerotwo/lib/python3.10/site-packages/streamlit/type_util.py\", line 956, in data_frame_to_bytes\n",
      "    table = pa.Table.from_pandas(df)\n",
      "  File \"pyarrow/table.pxi\", line 3457, in pyarrow.lib.Table.from_pandas\n",
      "  File \"/Users/rmitta/opt/anaconda3/envs/zerotwo/lib/python3.10/site-packages/pyarrow/pandas_compat.py\", line 553, in dataframe_to_arrays\n",
      "    convert_fields) = _get_columns_to_convert(df, schema, preserve_index,\n",
      "  File \"/Users/rmitta/opt/anaconda3/envs/zerotwo/lib/python3.10/site-packages/pyarrow/pandas_compat.py\", line 337, in _get_columns_to_convert\n",
      "    raise ValueError(\n",
      "ValueError: Duplicate column names found: ['city', 'R2', 'RRMSE', 'year', '', 'spatial (%)', 'r2_temporal', 'spatial (%)']\n",
      "2024-09-07 12:44:56.336 Uncaught app exception\n",
      "Traceback (most recent call last):\n",
      "  File \"/Users/rmitta/opt/anaconda3/envs/zerotwo/lib/python3.10/site-packages/streamlit/runtime/scriptrunner/script_runner.py\", line 542, in _run_script\n",
      "    exec(code, module.__dict__)\n",
      "  File \"/Volumes/Fatboy/Indian Traffic/cities/streamlit/cities/pages/2 Model Results.py\", line 31, in <module>\n",
      "    st.dataframe(metrics)\n",
      "  File \"/Users/rmitta/opt/anaconda3/envs/zerotwo/lib/python3.10/site-packages/streamlit/runtime/metrics_util.py\", line 397, in wrapped_func\n",
      "    result = non_optional_func(*args, **kwargs)\n",
      "  File \"/Users/rmitta/opt/anaconda3/envs/zerotwo/lib/python3.10/site-packages/streamlit/elements/arrow.py\", line 231, in dataframe\n",
      "    proto.data = type_util.data_frame_to_bytes(data_df)\n",
      "  File \"/Users/rmitta/opt/anaconda3/envs/zerotwo/lib/python3.10/site-packages/streamlit/type_util.py\", line 956, in data_frame_to_bytes\n",
      "    table = pa.Table.from_pandas(df)\n",
      "  File \"pyarrow/table.pxi\", line 3457, in pyarrow.lib.Table.from_pandas\n",
      "  File \"/Users/rmitta/opt/anaconda3/envs/zerotwo/lib/python3.10/site-packages/pyarrow/pandas_compat.py\", line 553, in dataframe_to_arrays\n",
      "    convert_fields) = _get_columns_to_convert(df, schema, preserve_index,\n",
      "  File \"/Users/rmitta/opt/anaconda3/envs/zerotwo/lib/python3.10/site-packages/pyarrow/pandas_compat.py\", line 337, in _get_columns_to_convert\n",
      "    raise ValueError(\n",
      "ValueError: Duplicate column names found: ['city', 'R2', 'RRMSE', 'year', 'SHAP ', 'spatial (%)', 'r2_temporal', 'spatial (%)']\n",
      "2024-09-07 12:44:58.471 Uncaught app exception\n",
      "Traceback (most recent call last):\n",
      "  File \"/Users/rmitta/opt/anaconda3/envs/zerotwo/lib/python3.10/site-packages/streamlit/runtime/scriptrunner/script_runner.py\", line 542, in _run_script\n",
      "    exec(code, module.__dict__)\n",
      "  File \"/Volumes/Fatboy/Indian Traffic/cities/streamlit/cities/pages/2 Model Results.py\", line 31, in <module>\n",
      "    st.dataframe(metrics)\n",
      "  File \"/Users/rmitta/opt/anaconda3/envs/zerotwo/lib/python3.10/site-packages/streamlit/runtime/metrics_util.py\", line 397, in wrapped_func\n",
      "    result = non_optional_func(*args, **kwargs)\n",
      "  File \"/Users/rmitta/opt/anaconda3/envs/zerotwo/lib/python3.10/site-packages/streamlit/elements/arrow.py\", line 231, in dataframe\n",
      "    proto.data = type_util.data_frame_to_bytes(data_df)\n",
      "  File \"/Users/rmitta/opt/anaconda3/envs/zerotwo/lib/python3.10/site-packages/streamlit/type_util.py\", line 956, in data_frame_to_bytes\n",
      "    table = pa.Table.from_pandas(df)\n",
      "  File \"pyarrow/table.pxi\", line 3457, in pyarrow.lib.Table.from_pandas\n",
      "  File \"/Users/rmitta/opt/anaconda3/envs/zerotwo/lib/python3.10/site-packages/pyarrow/pandas_compat.py\", line 553, in dataframe_to_arrays\n",
      "    convert_fields) = _get_columns_to_convert(df, schema, preserve_index,\n",
      "  File \"/Users/rmitta/opt/anaconda3/envs/zerotwo/lib/python3.10/site-packages/pyarrow/pandas_compat.py\", line 337, in _get_columns_to_convert\n",
      "    raise ValueError(\n",
      "ValueError: Duplicate column names found: ['city', 'R2', 'RRMSE', 'year', 'SHAP T', 'spatial (%)', 'r2_temporal', 'spatial (%)']\n",
      "2024-09-07 12:45:01.955 Uncaught app exception\n",
      "Traceback (most recent call last):\n",
      "  File \"/Users/rmitta/opt/anaconda3/envs/zerotwo/lib/python3.10/site-packages/streamlit/runtime/scriptrunner/script_runner.py\", line 542, in _run_script\n",
      "    exec(code, module.__dict__)\n",
      "  File \"/Volumes/Fatboy/Indian Traffic/cities/streamlit/cities/pages/2 Model Results.py\", line 31, in <module>\n",
      "    st.dataframe(metrics)\n",
      "  File \"/Users/rmitta/opt/anaconda3/envs/zerotwo/lib/python3.10/site-packages/streamlit/runtime/metrics_util.py\", line 397, in wrapped_func\n",
      "    result = non_optional_func(*args, **kwargs)\n",
      "  File \"/Users/rmitta/opt/anaconda3/envs/zerotwo/lib/python3.10/site-packages/streamlit/elements/arrow.py\", line 231, in dataframe\n",
      "    proto.data = type_util.data_frame_to_bytes(data_df)\n",
      "  File \"/Users/rmitta/opt/anaconda3/envs/zerotwo/lib/python3.10/site-packages/streamlit/type_util.py\", line 956, in data_frame_to_bytes\n",
      "    table = pa.Table.from_pandas(df)\n",
      "  File \"pyarrow/table.pxi\", line 3457, in pyarrow.lib.Table.from_pandas\n",
      "  File \"/Users/rmitta/opt/anaconda3/envs/zerotwo/lib/python3.10/site-packages/pyarrow/pandas_compat.py\", line 553, in dataframe_to_arrays\n",
      "    convert_fields) = _get_columns_to_convert(df, schema, preserve_index,\n",
      "  File \"/Users/rmitta/opt/anaconda3/envs/zerotwo/lib/python3.10/site-packages/pyarrow/pandas_compat.py\", line 337, in _get_columns_to_convert\n",
      "    raise ValueError(\n",
      "ValueError: Duplicate column names found: ['city', 'R2', 'RRMSE', 'year', 'SHAP Temporal ()', 'spatial (%)', 'r2_temporal', 'spatial (%)']\n",
      "2024-09-07 12:45:04.092 Uncaught app exception\n",
      "Traceback (most recent call last):\n",
      "  File \"/Users/rmitta/opt/anaconda3/envs/zerotwo/lib/python3.10/site-packages/streamlit/runtime/scriptrunner/script_runner.py\", line 542, in _run_script\n",
      "    exec(code, module.__dict__)\n",
      "  File \"/Volumes/Fatboy/Indian Traffic/cities/streamlit/cities/pages/2 Model Results.py\", line 31, in <module>\n",
      "    st.dataframe(metrics)\n",
      "  File \"/Users/rmitta/opt/anaconda3/envs/zerotwo/lib/python3.10/site-packages/streamlit/runtime/metrics_util.py\", line 397, in wrapped_func\n",
      "    result = non_optional_func(*args, **kwargs)\n",
      "  File \"/Users/rmitta/opt/anaconda3/envs/zerotwo/lib/python3.10/site-packages/streamlit/elements/arrow.py\", line 231, in dataframe\n",
      "    proto.data = type_util.data_frame_to_bytes(data_df)\n",
      "  File \"/Users/rmitta/opt/anaconda3/envs/zerotwo/lib/python3.10/site-packages/streamlit/type_util.py\", line 956, in data_frame_to_bytes\n",
      "    table = pa.Table.from_pandas(df)\n",
      "  File \"pyarrow/table.pxi\", line 3457, in pyarrow.lib.Table.from_pandas\n",
      "  File \"/Users/rmitta/opt/anaconda3/envs/zerotwo/lib/python3.10/site-packages/pyarrow/pandas_compat.py\", line 553, in dataframe_to_arrays\n",
      "    convert_fields) = _get_columns_to_convert(df, schema, preserve_index,\n",
      "  File \"/Users/rmitta/opt/anaconda3/envs/zerotwo/lib/python3.10/site-packages/pyarrow/pandas_compat.py\", line 337, in _get_columns_to_convert\n",
      "    raise ValueError(\n",
      "ValueError: Duplicate column names found: ['city', 'R2', 'RRMSE', 'year', 'SHAP Temporal %', 'spatial (%)', 'r2_temporal', 'spatial (%)']\n",
      "2024-09-07 12:45:12.548 Uncaught app exception\n",
      "Traceback (most recent call last):\n",
      "  File \"/Users/rmitta/opt/anaconda3/envs/zerotwo/lib/python3.10/site-packages/streamlit/runtime/scriptrunner/script_runner.py\", line 542, in _run_script\n",
      "    exec(code, module.__dict__)\n",
      "  File \"/Volumes/Fatboy/Indian Traffic/cities/streamlit/cities/pages/2 Model Results.py\", line 142, in <module>\n",
      "    metrics_pie = metrics[metrics['city'] == st.session_state.selected_city.lower()][['temporal (%)', 'spatial (%)']].iloc[0].reset_index()\n",
      "  File \"/Users/rmitta/opt/anaconda3/envs/zerotwo/lib/python3.10/site-packages/pandas/core/frame.py\", line 3511, in __getitem__\n",
      "    indexer = self.columns._get_indexer_strict(key, \"columns\")[1]\n",
      "  File \"/Users/rmitta/opt/anaconda3/envs/zerotwo/lib/python3.10/site-packages/pandas/core/indexes/base.py\", line 5796, in _get_indexer_strict\n",
      "    self._raise_if_missing(keyarr, indexer, axis_name)\n",
      "  File \"/Users/rmitta/opt/anaconda3/envs/zerotwo/lib/python3.10/site-packages/pandas/core/indexes/base.py\", line 5859, in _raise_if_missing\n",
      "    raise KeyError(f\"{not_found} not in index\")\n",
      "KeyError: \"['temporal (%)'] not in index\"\n",
      "2024-09-07 12:45:13.154 Uncaught app exception\n",
      "Traceback (most recent call last):\n",
      "  File \"/Users/rmitta/opt/anaconda3/envs/zerotwo/lib/python3.10/site-packages/streamlit/runtime/scriptrunner/script_runner.py\", line 542, in _run_script\n",
      "    exec(code, module.__dict__)\n",
      "  File \"/Volumes/Fatboy/Indian Traffic/cities/streamlit/cities/pages/2 Model Results.py\", line 142, in <module>\n",
      "    metrics_pie = metrics[metrics['city'] == st.session_state.selected_city.lower()][['temporal (%)', 'spatial (%)']].iloc[0].reset_index()\n",
      "  File \"/Users/rmitta/opt/anaconda3/envs/zerotwo/lib/python3.10/site-packages/pandas/core/frame.py\", line 3511, in __getitem__\n",
      "    indexer = self.columns._get_indexer_strict(key, \"columns\")[1]\n",
      "  File \"/Users/rmitta/opt/anaconda3/envs/zerotwo/lib/python3.10/site-packages/pandas/core/indexes/base.py\", line 5796, in _get_indexer_strict\n",
      "    self._raise_if_missing(keyarr, indexer, axis_name)\n",
      "  File \"/Users/rmitta/opt/anaconda3/envs/zerotwo/lib/python3.10/site-packages/pandas/core/indexes/base.py\", line 5859, in _raise_if_missing\n",
      "    raise KeyError(f\"{not_found} not in index\")\n",
      "KeyError: \"['temporal (%)'] not in index\"\n",
      "2024-09-07 12:45:18.748 Uncaught app exception\n",
      "Traceback (most recent call last):\n",
      "  File \"/Users/rmitta/opt/anaconda3/envs/zerotwo/lib/python3.10/site-packages/streamlit/runtime/scriptrunner/script_runner.py\", line 542, in _run_script\n",
      "    exec(code, module.__dict__)\n",
      "  File \"/Volumes/Fatboy/Indian Traffic/cities/streamlit/cities/pages/2 Model Results.py\", line 31, in <module>\n",
      "    st.dataframe(metrics)\n",
      "  File \"/Users/rmitta/opt/anaconda3/envs/zerotwo/lib/python3.10/site-packages/streamlit/runtime/metrics_util.py\", line 397, in wrapped_func\n",
      "    result = non_optional_func(*args, **kwargs)\n",
      "  File \"/Users/rmitta/opt/anaconda3/envs/zerotwo/lib/python3.10/site-packages/streamlit/elements/arrow.py\", line 231, in dataframe\n",
      "    proto.data = type_util.data_frame_to_bytes(data_df)\n",
      "  File \"/Users/rmitta/opt/anaconda3/envs/zerotwo/lib/python3.10/site-packages/streamlit/type_util.py\", line 956, in data_frame_to_bytes\n",
      "    table = pa.Table.from_pandas(df)\n",
      "  File \"pyarrow/table.pxi\", line 3457, in pyarrow.lib.Table.from_pandas\n",
      "  File \"/Users/rmitta/opt/anaconda3/envs/zerotwo/lib/python3.10/site-packages/pyarrow/pandas_compat.py\", line 553, in dataframe_to_arrays\n",
      "    convert_fields) = _get_columns_to_convert(df, schema, preserve_index,\n",
      "  File \"/Users/rmitta/opt/anaconda3/envs/zerotwo/lib/python3.10/site-packages/pyarrow/pandas_compat.py\", line 337, in _get_columns_to_convert\n",
      "    raise ValueError(\n",
      "ValueError: Duplicate column names found: ['city', 'R2', 'RRMSE', 'year', 'SHAP Temporal %', 'SHAP Temporal %', 'r2_temporal', 'r2_spatial']\n",
      "2024-09-07 12:46:07.315 Uncaught app exception\n",
      "Traceback (most recent call last):\n",
      "  File \"/Users/rmitta/opt/anaconda3/envs/zerotwo/lib/python3.10/site-packages/streamlit/runtime/scriptrunner/script_runner.py\", line 542, in _run_script\n",
      "    exec(code, module.__dict__)\n",
      "  File \"/Volumes/Fatboy/Indian Traffic/cities/streamlit/cities/pages/2 Model Results.py\", line 31, in <module>\n",
      "    st.dataframe(metrics)\n",
      "  File \"/Users/rmitta/opt/anaconda3/envs/zerotwo/lib/python3.10/site-packages/streamlit/runtime/metrics_util.py\", line 397, in wrapped_func\n",
      "    result = non_optional_func(*args, **kwargs)\n",
      "  File \"/Users/rmitta/opt/anaconda3/envs/zerotwo/lib/python3.10/site-packages/streamlit/elements/arrow.py\", line 231, in dataframe\n",
      "    proto.data = type_util.data_frame_to_bytes(data_df)\n",
      "  File \"/Users/rmitta/opt/anaconda3/envs/zerotwo/lib/python3.10/site-packages/streamlit/type_util.py\", line 956, in data_frame_to_bytes\n",
      "    table = pa.Table.from_pandas(df)\n",
      "  File \"pyarrow/table.pxi\", line 3457, in pyarrow.lib.Table.from_pandas\n",
      "  File \"/Users/rmitta/opt/anaconda3/envs/zerotwo/lib/python3.10/site-packages/pyarrow/pandas_compat.py\", line 553, in dataframe_to_arrays\n",
      "    convert_fields) = _get_columns_to_convert(df, schema, preserve_index,\n",
      "  File \"/Users/rmitta/opt/anaconda3/envs/zerotwo/lib/python3.10/site-packages/pyarrow/pandas_compat.py\", line 337, in _get_columns_to_convert\n",
      "    raise ValueError(\n",
      "ValueError: Duplicate column names found: ['city', 'R2', 'RRMSE', 'year', 'SHAP Temporal %', 'SHAP Temporal %', 'r2_temporal', 'r2_spatial']\n",
      "2024-09-07 12:46:20.458 Uncaught app exception\n",
      "Traceback (most recent call last):\n",
      "  File \"/Users/rmitta/opt/anaconda3/envs/zerotwo/lib/python3.10/site-packages/streamlit/runtime/scriptrunner/script_runner.py\", line 542, in _run_script\n",
      "    exec(code, module.__dict__)\n",
      "  File \"/Volumes/Fatboy/Indian Traffic/cities/streamlit/cities/pages/2 Model Results.py\", line 142, in <module>\n",
      "    metrics_pie = metrics[metrics['city'] == st.session_state.selected_city.lower()][['temporal (%)', 'spatial (%)']].iloc[0].reset_index()\n",
      "  File \"/Users/rmitta/opt/anaconda3/envs/zerotwo/lib/python3.10/site-packages/pandas/core/frame.py\", line 3511, in __getitem__\n",
      "    indexer = self.columns._get_indexer_strict(key, \"columns\")[1]\n",
      "  File \"/Users/rmitta/opt/anaconda3/envs/zerotwo/lib/python3.10/site-packages/pandas/core/indexes/base.py\", line 5796, in _get_indexer_strict\n",
      "    self._raise_if_missing(keyarr, indexer, axis_name)\n",
      "  File \"/Users/rmitta/opt/anaconda3/envs/zerotwo/lib/python3.10/site-packages/pandas/core/indexes/base.py\", line 5856, in _raise_if_missing\n",
      "    raise KeyError(f\"None of [{key}] are in the [{axis_name}]\")\n",
      "KeyError: \"None of [Index(['temporal (%)', 'spatial (%)'], dtype='object')] are in the [columns]\"\n",
      "2024-09-07 12:46:21.032 Uncaught app exception\n",
      "Traceback (most recent call last):\n",
      "  File \"/Users/rmitta/opt/anaconda3/envs/zerotwo/lib/python3.10/site-packages/streamlit/runtime/scriptrunner/script_runner.py\", line 542, in _run_script\n",
      "    exec(code, module.__dict__)\n",
      "  File \"/Volumes/Fatboy/Indian Traffic/cities/streamlit/cities/pages/2 Model Results.py\", line 142, in <module>\n",
      "    metrics_pie = metrics[metrics['city'] == st.session_state.selected_city.lower()][['temporal (%)', 'spatial (%)']].iloc[0].reset_index()\n",
      "  File \"/Users/rmitta/opt/anaconda3/envs/zerotwo/lib/python3.10/site-packages/pandas/core/frame.py\", line 3511, in __getitem__\n",
      "    indexer = self.columns._get_indexer_strict(key, \"columns\")[1]\n",
      "  File \"/Users/rmitta/opt/anaconda3/envs/zerotwo/lib/python3.10/site-packages/pandas/core/indexes/base.py\", line 5796, in _get_indexer_strict\n",
      "    self._raise_if_missing(keyarr, indexer, axis_name)\n",
      "  File \"/Users/rmitta/opt/anaconda3/envs/zerotwo/lib/python3.10/site-packages/pandas/core/indexes/base.py\", line 5856, in _raise_if_missing\n",
      "    raise KeyError(f\"None of [{key}] are in the [{axis_name}]\")\n",
      "KeyError: \"None of [Index(['temporal (%)', 'spatial (%)'], dtype='object')] are in the [columns]\"\n",
      "2024-09-07 12:47:26.213 Uncaught app exception\n",
      "Traceback (most recent call last):\n",
      "  File \"/Users/rmitta/opt/anaconda3/envs/zerotwo/lib/python3.10/site-packages/streamlit/runtime/scriptrunner/script_runner.py\", line 542, in _run_script\n",
      "    exec(code, module.__dict__)\n",
      "  File \"/Volumes/Fatboy/Indian Traffic/cities/streamlit/cities/pages/2 Model Results.py\", line 142, in <module>\n",
      "    metrics_pie = metrics[metrics['city'] == st.session_state.selected_city.lower()][['SHAP Temporal %', 'spatial (%)']].iloc[0].reset_index()\n",
      "  File \"/Users/rmitta/opt/anaconda3/envs/zerotwo/lib/python3.10/site-packages/pandas/core/frame.py\", line 3511, in __getitem__\n",
      "    indexer = self.columns._get_indexer_strict(key, \"columns\")[1]\n",
      "  File \"/Users/rmitta/opt/anaconda3/envs/zerotwo/lib/python3.10/site-packages/pandas/core/indexes/base.py\", line 5796, in _get_indexer_strict\n",
      "    self._raise_if_missing(keyarr, indexer, axis_name)\n",
      "  File \"/Users/rmitta/opt/anaconda3/envs/zerotwo/lib/python3.10/site-packages/pandas/core/indexes/base.py\", line 5859, in _raise_if_missing\n",
      "    raise KeyError(f\"{not_found} not in index\")\n",
      "KeyError: \"['spatial (%)'] not in index\"\n",
      "2024-09-07 12:53:57.422 Uncaught app exception\n",
      "Traceback (most recent call last):\n",
      "  File \"/Users/rmitta/opt/anaconda3/envs/zerotwo/lib/python3.10/site-packages/streamlit/runtime/scriptrunner/script_runner.py\", line 542, in _run_script\n",
      "    exec(code, module.__dict__)\n",
      "  File \"/Volumes/Fatboy/Indian Traffic/cities/streamlit/cities/pages/2 Model Results.py\", line 149, in <module>\n",
      "    s\n",
      "NameError: name 's' is not defined\n"
     ]
    }
   ],
   "source": [
    "!streamlit run Data_Overview.py"
   ]
  },
  {
   "cell_type": "code",
   "execution_count": 7,
   "metadata": {},
   "outputs": [],
   "source": [
    "p = 'data/variability/bhopal/2021/car_F_COUNT_variability.png'"
   ]
  },
  {
   "cell_type": "code",
   "execution_count": 8,
   "metadata": {},
   "outputs": [
    {
     "name": "stdout",
     "output_type": "stream",
     "text": [
      "File exists\n"
     ]
    }
   ],
   "source": [
    "# chceck if p has a file\n",
    "import os\n",
    "if os.path.isfile(p):\n",
    "       print('File exists')"
   ]
  }
 ],
 "metadata": {
  "kernelspec": {
   "display_name": "Python 3.10.6 ('zerotwo')",
   "language": "python",
   "name": "python3"
  },
  "language_info": {
   "codemirror_mode": {
    "name": "ipython",
    "version": 3
   },
   "file_extension": ".py",
   "mimetype": "text/x-python",
   "name": "python",
   "nbconvert_exporter": "python",
   "pygments_lexer": "ipython3",
   "version": "3.10.6"
  },
  "orig_nbformat": 4,
  "vscode": {
   "interpreter": {
    "hash": "9bfb04bc2ddf749979761a4feac0c518cf5ca390f648d1feb34c0cf89edffd23"
   }
  }
 },
 "nbformat": 4,
 "nbformat_minor": 2
}
