{
 "cells": [
  {
   "cell_type": "code",
   "execution_count": null,
   "metadata": {},
   "outputs": [
    {
     "name": "stdout",
     "output_type": "stream",
     "text": [
      "\u001b[0m\n",
      "\u001b[34m\u001b[1m  You can now view your Streamlit app in your browser.\u001b[0m\n",
      "\u001b[0m\n",
      "\u001b[34m  Local URL: \u001b[0m\u001b[1mhttp://localhost:8501\u001b[0m\n",
      "\u001b[34m  Network URL: \u001b[0m\u001b[1mhttp://10.10.8.2:8501\u001b[0m\n",
      "\u001b[0m\n",
      "\u001b[34m\u001b[1m  For better performance, install the Watchdog module:\u001b[0m\n",
      "\n",
      "  $ xcode-select --install\n",
      "  $ pip install watchdog\n",
      "            \u001b[0m\n",
      "2025-07-23 18:37:33.723 Uncaught app execution\n",
      "Traceback (most recent call last):\n",
      "  File \"/Users/rmitta/opt/anaconda3/envs/truskawka/lib/python3.10/site-packages/streamlit/runtime/scriptrunner/exec_code.py\", line 128, in exec_func_with_error_handling\n",
      "    result = func()\n",
      "  File \"/Users/rmitta/opt/anaconda3/envs/truskawka/lib/python3.10/site-packages/streamlit/runtime/scriptrunner/script_runner.py\", line 667, in code_to_exec\n",
      "    _mpa_v1(self._main_script_path)\n",
      "  File \"/Users/rmitta/opt/anaconda3/envs/truskawka/lib/python3.10/site-packages/streamlit/runtime/scriptrunner/script_runner.py\", line 165, in _mpa_v1\n",
      "    page.run()\n",
      "  File \"/Users/rmitta/opt/anaconda3/envs/truskawka/lib/python3.10/site-packages/streamlit/navigation/page.py\", line 300, in run\n",
      "    exec(code, module.__dict__)  # noqa: S102\n",
      "  File \"/Users/rmitta/Documents/GitHub/cities/pages/6 ðŸ†• Kaya Identity.py\", line 72, in <module>\n",
      "    df_fc_ratio = pd.read_csv(f'data/kaya_identity/{select_year}/fc_ratio.csv')\n",
      "  File \"/Users/rmitta/opt/anaconda3/envs/truskawka/lib/python3.10/site-packages/pandas/io/parsers/readers.py\", line 1026, in read_csv\n",
      "    return _read(filepath_or_buffer, kwds)\n",
      "  File \"/Users/rmitta/opt/anaconda3/envs/truskawka/lib/python3.10/site-packages/pandas/io/parsers/readers.py\", line 620, in _read\n",
      "    parser = TextFileReader(filepath_or_buffer, **kwds)\n",
      "  File \"/Users/rmitta/opt/anaconda3/envs/truskawka/lib/python3.10/site-packages/pandas/io/parsers/readers.py\", line 1620, in __init__\n",
      "    self._engine = self._make_engine(f, self.engine)\n",
      "  File \"/Users/rmitta/opt/anaconda3/envs/truskawka/lib/python3.10/site-packages/pandas/io/parsers/readers.py\", line 1880, in _make_engine\n",
      "    self.handles = get_handle(\n",
      "  File \"/Users/rmitta/opt/anaconda3/envs/truskawka/lib/python3.10/site-packages/pandas/io/common.py\", line 873, in get_handle\n",
      "    handle = open(\n",
      "FileNotFoundError: [Errno 2] No such file or directory: 'data/kaya_identity/2021/fc_ratio.csv'\n",
      "2025-07-23 18:37:37.987 Uncaught app execution\n",
      "Traceback (most recent call last):\n",
      "  File \"/Users/rmitta/opt/anaconda3/envs/truskawka/lib/python3.10/site-packages/streamlit/runtime/scriptrunner/exec_code.py\", line 128, in exec_func_with_error_handling\n",
      "    result = func()\n",
      "  File \"/Users/rmitta/opt/anaconda3/envs/truskawka/lib/python3.10/site-packages/streamlit/runtime/scriptrunner/script_runner.py\", line 667, in code_to_exec\n",
      "    _mpa_v1(self._main_script_path)\n",
      "  File \"/Users/rmitta/opt/anaconda3/envs/truskawka/lib/python3.10/site-packages/streamlit/runtime/scriptrunner/script_runner.py\", line 165, in _mpa_v1\n",
      "    page.run()\n",
      "  File \"/Users/rmitta/opt/anaconda3/envs/truskawka/lib/python3.10/site-packages/streamlit/navigation/page.py\", line 300, in run\n",
      "    exec(code, module.__dict__)  # noqa: S102\n",
      "  File \"/Users/rmitta/Documents/GitHub/cities/pages/6 ðŸ†• Kaya Identity.py\", line 72, in <module>\n",
      "    df_fc_ratio = pd.read_csv(f'data//fc_ratio.csv')\n",
      "  File \"/Users/rmitta/opt/anaconda3/envs/truskawka/lib/python3.10/site-packages/pandas/io/parsers/readers.py\", line 1026, in read_csv\n",
      "    return _read(filepath_or_buffer, kwds)\n",
      "  File \"/Users/rmitta/opt/anaconda3/envs/truskawka/lib/python3.10/site-packages/pandas/io/parsers/readers.py\", line 620, in _read\n",
      "    parser = TextFileReader(filepath_or_buffer, **kwds)\n",
      "  File \"/Users/rmitta/opt/anaconda3/envs/truskawka/lib/python3.10/site-packages/pandas/io/parsers/readers.py\", line 1620, in __init__\n",
      "    self._engine = self._make_engine(f, self.engine)\n",
      "  File \"/Users/rmitta/opt/anaconda3/envs/truskawka/lib/python3.10/site-packages/pandas/io/parsers/readers.py\", line 1880, in _make_engine\n",
      "    self.handles = get_handle(\n",
      "  File \"/Users/rmitta/opt/anaconda3/envs/truskawka/lib/python3.10/site-packages/pandas/io/common.py\", line 873, in get_handle\n",
      "    handle = open(\n",
      "FileNotFoundError: [Errno 2] No such file or directory: 'data//fc_ratio.csv'\n",
      "2025-07-23 18:37:45.278 Uncaught app execution\n",
      "Traceback (most recent call last):\n",
      "  File \"/Users/rmitta/opt/anaconda3/envs/truskawka/lib/python3.10/site-packages/streamlit/runtime/scriptrunner/exec_code.py\", line 128, in exec_func_with_error_handling\n",
      "    result = func()\n",
      "  File \"/Users/rmitta/opt/anaconda3/envs/truskawka/lib/python3.10/site-packages/streamlit/runtime/scriptrunner/script_runner.py\", line 667, in code_to_exec\n",
      "    _mpa_v1(self._main_script_path)\n",
      "  File \"/Users/rmitta/opt/anaconda3/envs/truskawka/lib/python3.10/site-packages/streamlit/runtime/scriptrunner/script_runner.py\", line 165, in _mpa_v1\n",
      "    page.run()\n",
      "  File \"/Users/rmitta/opt/anaconda3/envs/truskawka/lib/python3.10/site-packages/streamlit/navigation/page.py\", line 300, in run\n",
      "    exec(code, module.__dict__)  # noqa: S102\n",
      "  File \"/Users/rmitta/Documents/GitHub/cities/pages/6 ðŸ†• Kaya Identity.py\", line 72, in <module>\n",
      "    df_fc_ratio = pd.read_csv(f'data/data_final/dffc_ratio.csv')\n",
      "  File \"/Users/rmitta/opt/anaconda3/envs/truskawka/lib/python3.10/site-packages/pandas/io/parsers/readers.py\", line 1026, in read_csv\n",
      "    return _read(filepath_or_buffer, kwds)\n",
      "  File \"/Users/rmitta/opt/anaconda3/envs/truskawka/lib/python3.10/site-packages/pandas/io/parsers/readers.py\", line 620, in _read\n",
      "    parser = TextFileReader(filepath_or_buffer, **kwds)\n",
      "  File \"/Users/rmitta/opt/anaconda3/envs/truskawka/lib/python3.10/site-packages/pandas/io/parsers/readers.py\", line 1620, in __init__\n",
      "    self._engine = self._make_engine(f, self.engine)\n",
      "  File \"/Users/rmitta/opt/anaconda3/envs/truskawka/lib/python3.10/site-packages/pandas/io/parsers/readers.py\", line 1880, in _make_engine\n",
      "    self.handles = get_handle(\n",
      "  File \"/Users/rmitta/opt/anaconda3/envs/truskawka/lib/python3.10/site-packages/pandas/io/common.py\", line 873, in get_handle\n",
      "    handle = open(\n",
      "FileNotFoundError: [Errno 2] No such file or directory: 'data/data_final/fc_ratio.csv'\n",
      "2025-07-23 18:38:07.292 Uncaught app execution\n",
      "Traceback (most recent call last):\n",
      "  File \"/Users/rmitta/opt/anaconda3/envs/truskawka/lib/python3.10/site-packages/streamlit/runtime/scriptrunner/exec_code.py\", line 128, in exec_func_with_error_handling\n",
      "    result = func()\n",
      "  File \"/Users/rmitta/opt/anaconda3/envs/truskawka/lib/python3.10/site-packages/streamlit/runtime/scriptrunner/script_runner.py\", line 667, in code_to_exec\n",
      "    _mpa_v1(self._main_script_path)\n",
      "  File \"/Users/rmitta/opt/anaconda3/envs/truskawka/lib/python3.10/site-packages/streamlit/runtime/scriptrunner/script_runner.py\", line 165, in _mpa_v1\n",
      "    page.run()\n",
      "  File \"/Users/rmitta/opt/anaconda3/envs/truskawka/lib/python3.10/site-packages/streamlit/navigation/page.py\", line 300, in run\n",
      "    exec(code, module.__dict__)  # noqa: S102\n",
      "  File \"/Users/rmitta/Documents/GitHub/cities/pages/6 ðŸ†• Kaya Identity.py\", line 74, in <module>\n",
      "    df\n",
      "NameError: name 'df' is not defined\n",
      "2025-07-23 18:42:50.173 Uncaught app execution\n",
      "Traceback (most recent call last):\n",
      "  File \"/Users/rmitta/opt/anaconda3/envs/truskawka/lib/python3.10/site-packages/streamlit/runtime/scriptrunner/exec_code.py\", line 128, in exec_func_with_error_handling\n",
      "    result = func()\n",
      "  File \"/Users/rmitta/opt/anaconda3/envs/truskawka/lib/python3.10/site-packages/streamlit/runtime/scriptrunner/script_runner.py\", line 667, in code_to_exec\n",
      "    _mpa_v1(self._main_script_path)\n",
      "  File \"/Users/rmitta/opt/anaconda3/envs/truskawka/lib/python3.10/site-packages/streamlit/runtime/scriptrunner/script_runner.py\", line 165, in _mpa_v1\n",
      "    page.run()\n",
      "  File \"/Users/rmitta/opt/anaconda3/envs/truskawka/lib/python3.10/site-packages/streamlit/navigation/page.py\", line 300, in run\n",
      "    exec(code, module.__dict__)  # noqa: S102\n",
      "  File \"/Users/rmitta/Documents/GitHub/cities/pages/6 ðŸ†• Kaya Identity.py\", line 79, in <module>\n",
      "    sns.scatterplot(data=df_merge,x=x, y=y, s=100, alpha=0.7)\n",
      "  File \"/Users/rmitta/opt/anaconda3/envs/truskawka/lib/python3.10/site-packages/seaborn/relational.py\", line 615, in scatterplot\n",
      "    p = _ScatterPlotter(\n",
      "  File \"/Users/rmitta/opt/anaconda3/envs/truskawka/lib/python3.10/site-packages/seaborn/relational.py\", line 396, in __init__\n",
      "    super().__init__(data=data, variables=variables)\n",
      "  File \"/Users/rmitta/opt/anaconda3/envs/truskawka/lib/python3.10/site-packages/seaborn/_base.py\", line 634, in __init__\n",
      "    self.assign_variables(data, variables)\n",
      "  File \"/Users/rmitta/opt/anaconda3/envs/truskawka/lib/python3.10/site-packages/seaborn/_base.py\", line 679, in assign_variables\n",
      "    plot_data = PlotData(data, variables)\n",
      "  File \"/Users/rmitta/opt/anaconda3/envs/truskawka/lib/python3.10/site-packages/seaborn/_core/data.py\", line 58, in __init__\n",
      "    frame, names, ids = self._assign_variables(data, variables)\n",
      "  File \"/Users/rmitta/opt/anaconda3/envs/truskawka/lib/python3.10/site-packages/seaborn/_core/data.py\", line 232, in _assign_variables\n",
      "    raise ValueError(err)\n",
      "ValueError: Could not interpret value `gini_bc` for `x`. An entry with this name does not appear in `data`.\n",
      "2025-07-23 18:42:53.609 Uncaught app execution\n",
      "Traceback (most recent call last):\n",
      "  File \"/Users/rmitta/opt/anaconda3/envs/truskawka/lib/python3.10/site-packages/streamlit/runtime/scriptrunner/exec_code.py\", line 128, in exec_func_with_error_handling\n",
      "    result = func()\n",
      "  File \"/Users/rmitta/opt/anaconda3/envs/truskawka/lib/python3.10/site-packages/streamlit/runtime/scriptrunner/script_runner.py\", line 667, in code_to_exec\n",
      "    _mpa_v1(self._main_script_path)\n",
      "  File \"/Users/rmitta/opt/anaconda3/envs/truskawka/lib/python3.10/site-packages/streamlit/runtime/scriptrunner/script_runner.py\", line 165, in _mpa_v1\n",
      "    page.run()\n",
      "  File \"/Users/rmitta/opt/anaconda3/envs/truskawka/lib/python3.10/site-packages/streamlit/navigation/page.py\", line 300, in run\n",
      "    exec(code, module.__dict__)  # noqa: S102\n",
      "  File \"/Users/rmitta/Documents/GitHub/cities/pages/6 ðŸ†• Kaya Identity.py\", line 79, in <module>\n",
      "    sns.scatterplot(data=df_merge,x=x, y=y, s=100, alpha=0.7)\n",
      "  File \"/Users/rmitta/opt/anaconda3/envs/truskawka/lib/python3.10/site-packages/seaborn/relational.py\", line 615, in scatterplot\n",
      "    p = _ScatterPlotter(\n",
      "  File \"/Users/rmitta/opt/anaconda3/envs/truskawka/lib/python3.10/site-packages/seaborn/relational.py\", line 396, in __init__\n",
      "    super().__init__(data=data, variables=variables)\n",
      "  File \"/Users/rmitta/opt/anaconda3/envs/truskawka/lib/python3.10/site-packages/seaborn/_base.py\", line 634, in __init__\n",
      "    self.assign_variables(data, variables)\n",
      "  File \"/Users/rmitta/opt/anaconda3/envs/truskawka/lib/python3.10/site-packages/seaborn/_base.py\", line 679, in assign_variables\n",
      "    plot_data = PlotData(data, variables)\n",
      "  File \"/Users/rmitta/opt/anaconda3/envs/truskawka/lib/python3.10/site-packages/seaborn/_core/data.py\", line 58, in __init__\n",
      "    frame, names, ids = self._assign_variables(data, variables)\n",
      "  File \"/Users/rmitta/opt/anaconda3/envs/truskawka/lib/python3.10/site-packages/seaborn/_core/data.py\", line 232, in _assign_variables\n",
      "    raise ValueError(err)\n",
      "ValueError: Could not interpret value `gini_bc` for `x`. An entry with this name does not appear in `data`.\n",
      "2025-07-23 18:43:06.588 Uncaught app execution\n",
      "Traceback (most recent call last):\n",
      "  File \"/Users/rmitta/opt/anaconda3/envs/truskawka/lib/python3.10/site-packages/streamlit/runtime/scriptrunner/exec_code.py\", line 128, in exec_func_with_error_handling\n",
      "    result = func()\n",
      "  File \"/Users/rmitta/opt/anaconda3/envs/truskawka/lib/python3.10/site-packages/streamlit/runtime/scriptrunner/script_runner.py\", line 667, in code_to_exec\n",
      "    _mpa_v1(self._main_script_path)\n",
      "  File \"/Users/rmitta/opt/anaconda3/envs/truskawka/lib/python3.10/site-packages/streamlit/runtime/scriptrunner/script_runner.py\", line 165, in _mpa_v1\n",
      "    page.run()\n",
      "  File \"/Users/rmitta/opt/anaconda3/envs/truskawka/lib/python3.10/site-packages/streamlit/navigation/page.py\", line 300, in run\n",
      "    exec(code, module.__dict__)  # noqa: S102\n",
      "  File \"/Users/rmitta/Documents/GitHub/cities/pages/6 ðŸ†• Kaya Identity.py\", line 80, in <module>\n",
      "    sns.scatterplot(data=df_merge,x=x, y=y, s=100, alpha=0.7)\n",
      "  File \"/Users/rmitta/opt/anaconda3/envs/truskawka/lib/python3.10/site-packages/seaborn/relational.py\", line 615, in scatterplot\n",
      "    p = _ScatterPlotter(\n",
      "  File \"/Users/rmitta/opt/anaconda3/envs/truskawka/lib/python3.10/site-packages/seaborn/relational.py\", line 396, in __init__\n",
      "    super().__init__(data=data, variables=variables)\n",
      "  File \"/Users/rmitta/opt/anaconda3/envs/truskawka/lib/python3.10/site-packages/seaborn/_base.py\", line 634, in __init__\n",
      "    self.assign_variables(data, variables)\n",
      "  File \"/Users/rmitta/opt/anaconda3/envs/truskawka/lib/python3.10/site-packages/seaborn/_base.py\", line 679, in assign_variables\n",
      "    plot_data = PlotData(data, variables)\n",
      "  File \"/Users/rmitta/opt/anaconda3/envs/truskawka/lib/python3.10/site-packages/seaborn/_core/data.py\", line 58, in __init__\n",
      "    frame, names, ids = self._assign_variables(data, variables)\n",
      "  File \"/Users/rmitta/opt/anaconda3/envs/truskawka/lib/python3.10/site-packages/seaborn/_core/data.py\", line 232, in _assign_variables\n",
      "    raise ValueError(err)\n",
      "ValueError: Could not interpret value `gini_bc` for `x`. An entry with this name does not appear in `data`.\n",
      "2025-07-23 18:43:16.454 Uncaught app execution\n",
      "Traceback (most recent call last):\n",
      "  File \"/Users/rmitta/opt/anaconda3/envs/truskawka/lib/python3.10/site-packages/streamlit/runtime/scriptrunner/exec_code.py\", line 128, in exec_func_with_error_handling\n",
      "    result = func()\n",
      "  File \"/Users/rmitta/opt/anaconda3/envs/truskawka/lib/python3.10/site-packages/streamlit/runtime/scriptrunner/script_runner.py\", line 667, in code_to_exec\n",
      "    _mpa_v1(self._main_script_path)\n",
      "  File \"/Users/rmitta/opt/anaconda3/envs/truskawka/lib/python3.10/site-packages/streamlit/runtime/scriptrunner/script_runner.py\", line 165, in _mpa_v1\n",
      "    page.run()\n",
      "  File \"/Users/rmitta/opt/anaconda3/envs/truskawka/lib/python3.10/site-packages/streamlit/navigation/page.py\", line 300, in run\n",
      "    exec(code, module.__dict__)  # noqa: S102\n",
      "  File \"/Users/rmitta/Documents/GitHub/cities/pages/6 ðŸ†• Kaya Identity.py\", line 80, in <module>\n",
      "    sns.scatterplot(data=df_merge,x=x, y=y, s=100, alpha=0.7)\n",
      "  File \"/Users/rmitta/opt/anaconda3/envs/truskawka/lib/python3.10/site-packages/seaborn/relational.py\", line 615, in scatterplot\n",
      "    p = _ScatterPlotter(\n",
      "  File \"/Users/rmitta/opt/anaconda3/envs/truskawka/lib/python3.10/site-packages/seaborn/relational.py\", line 396, in __init__\n",
      "    super().__init__(data=data, variables=variables)\n",
      "  File \"/Users/rmitta/opt/anaconda3/envs/truskawka/lib/python3.10/site-packages/seaborn/_base.py\", line 634, in __init__\n",
      "    self.assign_variables(data, variables)\n",
      "  File \"/Users/rmitta/opt/anaconda3/envs/truskawka/lib/python3.10/site-packages/seaborn/_base.py\", line 679, in assign_variables\n",
      "    plot_data = PlotData(data, variables)\n",
      "  File \"/Users/rmitta/opt/anaconda3/envs/truskawka/lib/python3.10/site-packages/seaborn/_core/data.py\", line 58, in __init__\n",
      "    frame, names, ids = self._assign_variables(data, variables)\n",
      "  File \"/Users/rmitta/opt/anaconda3/envs/truskawka/lib/python3.10/site-packages/seaborn/_core/data.py\", line 232, in _assign_variables\n",
      "    raise ValueError(err)\n",
      "ValueError: Could not interpret value `gini_bc` for `x`. An entry with this name does not appear in `data`.\n",
      "2025-07-23 18:43:22.644 Uncaught app execution\n",
      "Traceback (most recent call last):\n",
      "  File \"/Users/rmitta/opt/anaconda3/envs/truskawka/lib/python3.10/site-packages/streamlit/runtime/scriptrunner/exec_code.py\", line 128, in exec_func_with_error_handling\n",
      "    result = func()\n",
      "  File \"/Users/rmitta/opt/anaconda3/envs/truskawka/lib/python3.10/site-packages/streamlit/runtime/scriptrunner/script_runner.py\", line 667, in code_to_exec\n",
      "    _mpa_v1(self._main_script_path)\n",
      "  File \"/Users/rmitta/opt/anaconda3/envs/truskawka/lib/python3.10/site-packages/streamlit/runtime/scriptrunner/script_runner.py\", line 165, in _mpa_v1\n",
      "    page.run()\n",
      "  File \"/Users/rmitta/opt/anaconda3/envs/truskawka/lib/python3.10/site-packages/streamlit/navigation/page.py\", line 300, in run\n",
      "    exec(code, module.__dict__)  # noqa: S102\n",
      "  File \"/Users/rmitta/Documents/GitHub/cities/pages/6 ðŸ†• Kaya Identity.py\", line 80, in <module>\n",
      "    sns.scatterplot(data=df_merge,x=x, y=y, s=100, alpha=0.7)\n",
      "  File \"/Users/rmitta/opt/anaconda3/envs/truskawka/lib/python3.10/site-packages/seaborn/relational.py\", line 615, in scatterplot\n",
      "    p = _ScatterPlotter(\n",
      "  File \"/Users/rmitta/opt/anaconda3/envs/truskawka/lib/python3.10/site-packages/seaborn/relational.py\", line 396, in __init__\n",
      "    super().__init__(data=data, variables=variables)\n",
      "  File \"/Users/rmitta/opt/anaconda3/envs/truskawka/lib/python3.10/site-packages/seaborn/_base.py\", line 634, in __init__\n",
      "    self.assign_variables(data, variables)\n",
      "  File \"/Users/rmitta/opt/anaconda3/envs/truskawka/lib/python3.10/site-packages/seaborn/_base.py\", line 679, in assign_variables\n",
      "    plot_data = PlotData(data, variables)\n",
      "  File \"/Users/rmitta/opt/anaconda3/envs/truskawka/lib/python3.10/site-packages/seaborn/_core/data.py\", line 58, in __init__\n",
      "    frame, names, ids = self._assign_variables(data, variables)\n",
      "  File \"/Users/rmitta/opt/anaconda3/envs/truskawka/lib/python3.10/site-packages/seaborn/_core/data.py\", line 232, in _assign_variables\n",
      "    raise ValueError(err)\n",
      "ValueError: Could not interpret value `gini_bc` for `x`. An entry with this name does not appear in `data`.\n",
      "2025-07-23 18:43:33.435 Uncaught app execution\n",
      "Traceback (most recent call last):\n",
      "  File \"/Users/rmitta/opt/anaconda3/envs/truskawka/lib/python3.10/site-packages/streamlit/runtime/scriptrunner/exec_code.py\", line 128, in exec_func_with_error_handling\n",
      "    result = func()\n",
      "  File \"/Users/rmitta/opt/anaconda3/envs/truskawka/lib/python3.10/site-packages/streamlit/runtime/scriptrunner/script_runner.py\", line 667, in code_to_exec\n",
      "    _mpa_v1(self._main_script_path)\n",
      "  File \"/Users/rmitta/opt/anaconda3/envs/truskawka/lib/python3.10/site-packages/streamlit/runtime/scriptrunner/script_runner.py\", line 165, in _mpa_v1\n",
      "    page.run()\n",
      "  File \"/Users/rmitta/opt/anaconda3/envs/truskawka/lib/python3.10/site-packages/streamlit/navigation/page.py\", line 300, in run\n",
      "    exec(code, module.__dict__)  # noqa: S102\n",
      "  File \"/Users/rmitta/Documents/GitHub/cities/pages/6 ðŸ†• Kaya Identity.py\", line 80, in <module>\n",
      "    sns.scatterplot(data=df_merge,x=x, y=y, s=100, alpha=0.7)\n",
      "  File \"/Users/rmitta/opt/anaconda3/envs/truskawka/lib/python3.10/site-packages/seaborn/relational.py\", line 615, in scatterplot\n",
      "    p = _ScatterPlotter(\n",
      "  File \"/Users/rmitta/opt/anaconda3/envs/truskawka/lib/python3.10/site-packages/seaborn/relational.py\", line 396, in __init__\n",
      "    super().__init__(data=data, variables=variables)\n",
      "  File \"/Users/rmitta/opt/anaconda3/envs/truskawka/lib/python3.10/site-packages/seaborn/_base.py\", line 634, in __init__\n",
      "    self.assign_variables(data, variables)\n",
      "  File \"/Users/rmitta/opt/anaconda3/envs/truskawka/lib/python3.10/site-packages/seaborn/_base.py\", line 679, in assign_variables\n",
      "    plot_data = PlotData(data, variables)\n",
      "  File \"/Users/rmitta/opt/anaconda3/envs/truskawka/lib/python3.10/site-packages/seaborn/_core/data.py\", line 58, in __init__\n",
      "    frame, names, ids = self._assign_variables(data, variables)\n",
      "  File \"/Users/rmitta/opt/anaconda3/envs/truskawka/lib/python3.10/site-packages/seaborn/_core/data.py\", line 232, in _assign_variables\n",
      "    raise ValueError(err)\n",
      "ValueError: Could not interpret value `gini_bc` for `x`. An entry with this name does not appear in `data`.\n",
      "2025-07-23 18:43:37.893 Uncaught app execution\n",
      "Traceback (most recent call last):\n",
      "  File \"/Users/rmitta/opt/anaconda3/envs/truskawka/lib/python3.10/site-packages/streamlit/runtime/scriptrunner/exec_code.py\", line 128, in exec_func_with_error_handling\n",
      "    result = func()\n",
      "  File \"/Users/rmitta/opt/anaconda3/envs/truskawka/lib/python3.10/site-packages/streamlit/runtime/scriptrunner/script_runner.py\", line 667, in code_to_exec\n",
      "    _mpa_v1(self._main_script_path)\n",
      "  File \"/Users/rmitta/opt/anaconda3/envs/truskawka/lib/python3.10/site-packages/streamlit/runtime/scriptrunner/script_runner.py\", line 165, in _mpa_v1\n",
      "    page.run()\n",
      "  File \"/Users/rmitta/opt/anaconda3/envs/truskawka/lib/python3.10/site-packages/streamlit/navigation/page.py\", line 300, in run\n",
      "    exec(code, module.__dict__)  # noqa: S102\n",
      "  File \"/Users/rmitta/Documents/GitHub/cities/pages/6 ðŸ†• Kaya Identity.py\", line 80, in <module>\n",
      "    sns.scatterplot(data=df_merge,x=x, y=y, s=100, alpha=0.7)\n",
      "  File \"/Users/rmitta/opt/anaconda3/envs/truskawka/lib/python3.10/site-packages/seaborn/relational.py\", line 615, in scatterplot\n",
      "    p = _ScatterPlotter(\n",
      "  File \"/Users/rmitta/opt/anaconda3/envs/truskawka/lib/python3.10/site-packages/seaborn/relational.py\", line 396, in __init__\n",
      "    super().__init__(data=data, variables=variables)\n",
      "  File \"/Users/rmitta/opt/anaconda3/envs/truskawka/lib/python3.10/site-packages/seaborn/_base.py\", line 634, in __init__\n",
      "    self.assign_variables(data, variables)\n",
      "  File \"/Users/rmitta/opt/anaconda3/envs/truskawka/lib/python3.10/site-packages/seaborn/_base.py\", line 679, in assign_variables\n",
      "    plot_data = PlotData(data, variables)\n",
      "  File \"/Users/rmitta/opt/anaconda3/envs/truskawka/lib/python3.10/site-packages/seaborn/_core/data.py\", line 58, in __init__\n",
      "    frame, names, ids = self._assign_variables(data, variables)\n",
      "  File \"/Users/rmitta/opt/anaconda3/envs/truskawka/lib/python3.10/site-packages/seaborn/_core/data.py\", line 232, in _assign_variables\n",
      "    raise ValueError(err)\n",
      "ValueError: Could not interpret value `gini_bc` for `x`. An entry with this name does not appear in `data`.\n",
      "2025-07-23 18:43:40.328 Uncaught app execution\n",
      "Traceback (most recent call last):\n",
      "  File \"/Users/rmitta/opt/anaconda3/envs/truskawka/lib/python3.10/site-packages/streamlit/runtime/scriptrunner/exec_code.py\", line 128, in exec_func_with_error_handling\n",
      "    result = func()\n",
      "  File \"/Users/rmitta/opt/anaconda3/envs/truskawka/lib/python3.10/site-packages/streamlit/runtime/scriptrunner/script_runner.py\", line 667, in code_to_exec\n",
      "    _mpa_v1(self._main_script_path)\n",
      "  File \"/Users/rmitta/opt/anaconda3/envs/truskawka/lib/python3.10/site-packages/streamlit/runtime/scriptrunner/script_runner.py\", line 165, in _mpa_v1\n",
      "    page.run()\n",
      "  File \"/Users/rmitta/opt/anaconda3/envs/truskawka/lib/python3.10/site-packages/streamlit/navigation/page.py\", line 300, in run\n",
      "    exec(code, module.__dict__)  # noqa: S102\n",
      "  File \"/Users/rmitta/Documents/GitHub/cities/pages/6 ðŸ†• Kaya Identity.py\", line 80, in <module>\n",
      "    sns.scatterplot(data=df_merge,x=x, y=y, s=100, alpha=0.7)\n",
      "  File \"/Users/rmitta/opt/anaconda3/envs/truskawka/lib/python3.10/site-packages/seaborn/relational.py\", line 615, in scatterplot\n",
      "    p = _ScatterPlotter(\n",
      "  File \"/Users/rmitta/opt/anaconda3/envs/truskawka/lib/python3.10/site-packages/seaborn/relational.py\", line 396, in __init__\n",
      "    super().__init__(data=data, variables=variables)\n",
      "  File \"/Users/rmitta/opt/anaconda3/envs/truskawka/lib/python3.10/site-packages/seaborn/_base.py\", line 634, in __init__\n",
      "    self.assign_variables(data, variables)\n",
      "  File \"/Users/rmitta/opt/anaconda3/envs/truskawka/lib/python3.10/site-packages/seaborn/_base.py\", line 679, in assign_variables\n",
      "    plot_data = PlotData(data, variables)\n",
      "  File \"/Users/rmitta/opt/anaconda3/envs/truskawka/lib/python3.10/site-packages/seaborn/_core/data.py\", line 58, in __init__\n",
      "    frame, names, ids = self._assign_variables(data, variables)\n",
      "  File \"/Users/rmitta/opt/anaconda3/envs/truskawka/lib/python3.10/site-packages/seaborn/_core/data.py\", line 232, in _assign_variables\n",
      "    raise ValueError(err)\n",
      "ValueError: Could not interpret value `gini_bc` for `x`. An entry with this name does not appear in `data`.\n",
      "2025-07-23 18:43:45.649 Uncaught app execution\n",
      "Traceback (most recent call last):\n",
      "  File \"/Users/rmitta/opt/anaconda3/envs/truskawka/lib/python3.10/site-packages/streamlit/runtime/scriptrunner/exec_code.py\", line 128, in exec_func_with_error_handling\n",
      "    result = func()\n",
      "  File \"/Users/rmitta/opt/anaconda3/envs/truskawka/lib/python3.10/site-packages/streamlit/runtime/scriptrunner/script_runner.py\", line 667, in code_to_exec\n",
      "    _mpa_v1(self._main_script_path)\n",
      "  File \"/Users/rmitta/opt/anaconda3/envs/truskawka/lib/python3.10/site-packages/streamlit/runtime/scriptrunner/script_runner.py\", line 165, in _mpa_v1\n",
      "    page.run()\n",
      "  File \"/Users/rmitta/opt/anaconda3/envs/truskawka/lib/python3.10/site-packages/streamlit/navigation/page.py\", line 300, in run\n",
      "    exec(code, module.__dict__)  # noqa: S102\n",
      "  File \"/Users/rmitta/Documents/GitHub/cities/pages/6 ðŸ†• Kaya Identity.py\", line 80, in <module>\n",
      "    sns.scatterplot(data=df_merge,x=x, y=y, s=100, alpha=0.7)\n",
      "  File \"/Users/rmitta/opt/anaconda3/envs/truskawka/lib/python3.10/site-packages/seaborn/relational.py\", line 615, in scatterplot\n",
      "    p = _ScatterPlotter(\n",
      "  File \"/Users/rmitta/opt/anaconda3/envs/truskawka/lib/python3.10/site-packages/seaborn/relational.py\", line 396, in __init__\n",
      "    super().__init__(data=data, variables=variables)\n",
      "  File \"/Users/rmitta/opt/anaconda3/envs/truskawka/lib/python3.10/site-packages/seaborn/_base.py\", line 634, in __init__\n",
      "    self.assign_variables(data, variables)\n",
      "  File \"/Users/rmitta/opt/anaconda3/envs/truskawka/lib/python3.10/site-packages/seaborn/_base.py\", line 679, in assign_variables\n",
      "    plot_data = PlotData(data, variables)\n",
      "  File \"/Users/rmitta/opt/anaconda3/envs/truskawka/lib/python3.10/site-packages/seaborn/_core/data.py\", line 58, in __init__\n",
      "    frame, names, ids = self._assign_variables(data, variables)\n",
      "  File \"/Users/rmitta/opt/anaconda3/envs/truskawka/lib/python3.10/site-packages/seaborn/_core/data.py\", line 232, in _assign_variables\n",
      "    raise ValueError(err)\n",
      "ValueError: Could not interpret value `gini_bc` for `x`. An entry with this name does not appear in `data`.\n",
      "2025-07-23 18:43:49.536 Uncaught app execution\n",
      "Traceback (most recent call last):\n",
      "  File \"/Users/rmitta/opt/anaconda3/envs/truskawka/lib/python3.10/site-packages/streamlit/runtime/scriptrunner/exec_code.py\", line 128, in exec_func_with_error_handling\n",
      "    result = func()\n",
      "  File \"/Users/rmitta/opt/anaconda3/envs/truskawka/lib/python3.10/site-packages/streamlit/runtime/scriptrunner/script_runner.py\", line 667, in code_to_exec\n",
      "    _mpa_v1(self._main_script_path)\n",
      "  File \"/Users/rmitta/opt/anaconda3/envs/truskawka/lib/python3.10/site-packages/streamlit/runtime/scriptrunner/script_runner.py\", line 165, in _mpa_v1\n",
      "    page.run()\n",
      "  File \"/Users/rmitta/opt/anaconda3/envs/truskawka/lib/python3.10/site-packages/streamlit/navigation/page.py\", line 300, in run\n",
      "    exec(code, module.__dict__)  # noqa: S102\n",
      "  File \"/Users/rmitta/Documents/GitHub/cities/pages/6 ðŸ†• Kaya Identity.py\", line 80, in <module>\n",
      "    sns.scatterplot(data=df_merge,x=x, y=y, s=100, alpha=0.7)\n",
      "  File \"/Users/rmitta/opt/anaconda3/envs/truskawka/lib/python3.10/site-packages/seaborn/relational.py\", line 615, in scatterplot\n",
      "    p = _ScatterPlotter(\n",
      "  File \"/Users/rmitta/opt/anaconda3/envs/truskawka/lib/python3.10/site-packages/seaborn/relational.py\", line 396, in __init__\n",
      "    super().__init__(data=data, variables=variables)\n",
      "  File \"/Users/rmitta/opt/anaconda3/envs/truskawka/lib/python3.10/site-packages/seaborn/_base.py\", line 634, in __init__\n",
      "    self.assign_variables(data, variables)\n",
      "  File \"/Users/rmitta/opt/anaconda3/envs/truskawka/lib/python3.10/site-packages/seaborn/_base.py\", line 679, in assign_variables\n",
      "    plot_data = PlotData(data, variables)\n",
      "  File \"/Users/rmitta/opt/anaconda3/envs/truskawka/lib/python3.10/site-packages/seaborn/_core/data.py\", line 58, in __init__\n",
      "    frame, names, ids = self._assign_variables(data, variables)\n",
      "  File \"/Users/rmitta/opt/anaconda3/envs/truskawka/lib/python3.10/site-packages/seaborn/_core/data.py\", line 232, in _assign_variables\n",
      "    raise ValueError(err)\n",
      "ValueError: Could not interpret value `gini_bc` for `x`. An entry with this name does not appear in `data`.\n",
      "2025-07-23 18:43:59.862 Uncaught app execution\n",
      "Traceback (most recent call last):\n",
      "  File \"/Users/rmitta/opt/anaconda3/envs/truskawka/lib/python3.10/site-packages/streamlit/runtime/scriptrunner/exec_code.py\", line 128, in exec_func_with_error_handling\n",
      "    result = func()\n",
      "  File \"/Users/rmitta/opt/anaconda3/envs/truskawka/lib/python3.10/site-packages/streamlit/runtime/scriptrunner/script_runner.py\", line 667, in code_to_exec\n",
      "    _mpa_v1(self._main_script_path)\n",
      "  File \"/Users/rmitta/opt/anaconda3/envs/truskawka/lib/python3.10/site-packages/streamlit/runtime/scriptrunner/script_runner.py\", line 165, in _mpa_v1\n",
      "    page.run()\n",
      "  File \"/Users/rmitta/opt/anaconda3/envs/truskawka/lib/python3.10/site-packages/streamlit/navigation/page.py\", line 300, in run\n",
      "    exec(code, module.__dict__)  # noqa: S102\n",
      "  File \"/Users/rmitta/Documents/GitHub/cities/pages/6 ðŸ†• Kaya Identity.py\", line 80, in <module>\n",
      "    sns.scatterplot(data=df_merge,x=x, y=y, s=100, alpha=0.7)\n",
      "  File \"/Users/rmitta/opt/anaconda3/envs/truskawka/lib/python3.10/site-packages/seaborn/relational.py\", line 615, in scatterplot\n",
      "    p = _ScatterPlotter(\n",
      "  File \"/Users/rmitta/opt/anaconda3/envs/truskawka/lib/python3.10/site-packages/seaborn/relational.py\", line 396, in __init__\n",
      "    super().__init__(data=data, variables=variables)\n",
      "  File \"/Users/rmitta/opt/anaconda3/envs/truskawka/lib/python3.10/site-packages/seaborn/_base.py\", line 634, in __init__\n",
      "    self.assign_variables(data, variables)\n",
      "  File \"/Users/rmitta/opt/anaconda3/envs/truskawka/lib/python3.10/site-packages/seaborn/_base.py\", line 679, in assign_variables\n",
      "    plot_data = PlotData(data, variables)\n",
      "  File \"/Users/rmitta/opt/anaconda3/envs/truskawka/lib/python3.10/site-packages/seaborn/_core/data.py\", line 58, in __init__\n",
      "    frame, names, ids = self._assign_variables(data, variables)\n",
      "  File \"/Users/rmitta/opt/anaconda3/envs/truskawka/lib/python3.10/site-packages/seaborn/_core/data.py\", line 232, in _assign_variables\n",
      "    raise ValueError(err)\n",
      "ValueError: Could not interpret value `gini_bc` for `x`. An entry with this name does not appear in `data`.\n",
      "2025-07-23 18:44:02.275 Uncaught app execution\n",
      "Traceback (most recent call last):\n",
      "  File \"/Users/rmitta/opt/anaconda3/envs/truskawka/lib/python3.10/site-packages/streamlit/runtime/scriptrunner/exec_code.py\", line 128, in exec_func_with_error_handling\n",
      "    result = func()\n",
      "  File \"/Users/rmitta/opt/anaconda3/envs/truskawka/lib/python3.10/site-packages/streamlit/runtime/scriptrunner/script_runner.py\", line 667, in code_to_exec\n",
      "    _mpa_v1(self._main_script_path)\n",
      "  File \"/Users/rmitta/opt/anaconda3/envs/truskawka/lib/python3.10/site-packages/streamlit/runtime/scriptrunner/script_runner.py\", line 165, in _mpa_v1\n",
      "    page.run()\n",
      "  File \"/Users/rmitta/opt/anaconda3/envs/truskawka/lib/python3.10/site-packages/streamlit/navigation/page.py\", line 300, in run\n",
      "    exec(code, module.__dict__)  # noqa: S102\n",
      "  File \"/Users/rmitta/Documents/GitHub/cities/pages/6 ðŸ†• Kaya Identity.py\", line 80, in <module>\n",
      "    sns.scatterplot(data=df_merge,x=x, y=y, s=100, alpha=0.7)\n",
      "  File \"/Users/rmitta/opt/anaconda3/envs/truskawka/lib/python3.10/site-packages/seaborn/relational.py\", line 615, in scatterplot\n",
      "    p = _ScatterPlotter(\n",
      "  File \"/Users/rmitta/opt/anaconda3/envs/truskawka/lib/python3.10/site-packages/seaborn/relational.py\", line 396, in __init__\n",
      "    super().__init__(data=data, variables=variables)\n",
      "  File \"/Users/rmitta/opt/anaconda3/envs/truskawka/lib/python3.10/site-packages/seaborn/_base.py\", line 634, in __init__\n",
      "    self.assign_variables(data, variables)\n",
      "  File \"/Users/rmitta/opt/anaconda3/envs/truskawka/lib/python3.10/site-packages/seaborn/_base.py\", line 679, in assign_variables\n",
      "    plot_data = PlotData(data, variables)\n",
      "  File \"/Users/rmitta/opt/anaconda3/envs/truskawka/lib/python3.10/site-packages/seaborn/_core/data.py\", line 58, in __init__\n",
      "    frame, names, ids = self._assign_variables(data, variables)\n",
      "  File \"/Users/rmitta/opt/anaconda3/envs/truskawka/lib/python3.10/site-packages/seaborn/_core/data.py\", line 232, in _assign_variables\n",
      "    raise ValueError(err)\n",
      "ValueError: Could not interpret value `gini_bc` for `x`. An entry with this name does not appear in `data`.\n",
      "2025-07-23 18:44:13.352 Uncaught app execution\n",
      "Traceback (most recent call last):\n",
      "  File \"/Users/rmitta/opt/anaconda3/envs/truskawka/lib/python3.10/site-packages/streamlit/runtime/scriptrunner/exec_code.py\", line 128, in exec_func_with_error_handling\n",
      "    result = func()\n",
      "  File \"/Users/rmitta/opt/anaconda3/envs/truskawka/lib/python3.10/site-packages/streamlit/runtime/scriptrunner/script_runner.py\", line 667, in code_to_exec\n",
      "    _mpa_v1(self._main_script_path)\n",
      "  File \"/Users/rmitta/opt/anaconda3/envs/truskawka/lib/python3.10/site-packages/streamlit/runtime/scriptrunner/script_runner.py\", line 165, in _mpa_v1\n",
      "    page.run()\n",
      "  File \"/Users/rmitta/opt/anaconda3/envs/truskawka/lib/python3.10/site-packages/streamlit/navigation/page.py\", line 300, in run\n",
      "    exec(code, module.__dict__)  # noqa: S102\n",
      "  File \"/Users/rmitta/Documents/GitHub/cities/pages/6 ðŸ†• Kaya Identity.py\", line 80, in <module>\n",
      "    sns.scatterplot(data=df_merge,x=x, y=y, s=100, alpha=0.7)\n",
      "  File \"/Users/rmitta/opt/anaconda3/envs/truskawka/lib/python3.10/site-packages/seaborn/relational.py\", line 615, in scatterplot\n",
      "    p = _ScatterPlotter(\n",
      "  File \"/Users/rmitta/opt/anaconda3/envs/truskawka/lib/python3.10/site-packages/seaborn/relational.py\", line 396, in __init__\n",
      "    super().__init__(data=data, variables=variables)\n",
      "  File \"/Users/rmitta/opt/anaconda3/envs/truskawka/lib/python3.10/site-packages/seaborn/_base.py\", line 634, in __init__\n",
      "    self.assign_variables(data, variables)\n",
      "  File \"/Users/rmitta/opt/anaconda3/envs/truskawka/lib/python3.10/site-packages/seaborn/_base.py\", line 679, in assign_variables\n",
      "    plot_data = PlotData(data, variables)\n",
      "  File \"/Users/rmitta/opt/anaconda3/envs/truskawka/lib/python3.10/site-packages/seaborn/_core/data.py\", line 58, in __init__\n",
      "    frame, names, ids = self._assign_variables(data, variables)\n",
      "  File \"/Users/rmitta/opt/anaconda3/envs/truskawka/lib/python3.10/site-packages/seaborn/_core/data.py\", line 232, in _assign_variables\n",
      "    raise ValueError(err)\n",
      "ValueError: Could not interpret value `populaton_2020` for `x`. An entry with this name does not appear in `data`.\n",
      "2025-07-23 18:44:17.951 Uncaught app execution\n",
      "Traceback (most recent call last):\n",
      "  File \"/Users/rmitta/opt/anaconda3/envs/truskawka/lib/python3.10/site-packages/streamlit/runtime/scriptrunner/exec_code.py\", line 128, in exec_func_with_error_handling\n",
      "    result = func()\n",
      "  File \"/Users/rmitta/opt/anaconda3/envs/truskawka/lib/python3.10/site-packages/streamlit/runtime/scriptrunner/script_runner.py\", line 667, in code_to_exec\n",
      "    _mpa_v1(self._main_script_path)\n",
      "  File \"/Users/rmitta/opt/anaconda3/envs/truskawka/lib/python3.10/site-packages/streamlit/runtime/scriptrunner/script_runner.py\", line 165, in _mpa_v1\n",
      "    page.run()\n",
      "  File \"/Users/rmitta/opt/anaconda3/envs/truskawka/lib/python3.10/site-packages/streamlit/navigation/page.py\", line 300, in run\n",
      "    exec(code, module.__dict__)  # noqa: S102\n",
      "  File \"/Users/rmitta/Documents/GitHub/cities/pages/6 ðŸ†• Kaya Identity.py\", line 80, in <module>\n",
      "    sns.scatterplot(data=df_merge,x=x, y=y, s=100, alpha=0.7)\n",
      "  File \"/Users/rmitta/opt/anaconda3/envs/truskawka/lib/python3.10/site-packages/seaborn/relational.py\", line 615, in scatterplot\n",
      "    p = _ScatterPlotter(\n",
      "  File \"/Users/rmitta/opt/anaconda3/envs/truskawka/lib/python3.10/site-packages/seaborn/relational.py\", line 396, in __init__\n",
      "    super().__init__(data=data, variables=variables)\n",
      "  File \"/Users/rmitta/opt/anaconda3/envs/truskawka/lib/python3.10/site-packages/seaborn/_base.py\", line 634, in __init__\n",
      "    self.assign_variables(data, variables)\n",
      "  File \"/Users/rmitta/opt/anaconda3/envs/truskawka/lib/python3.10/site-packages/seaborn/_base.py\", line 679, in assign_variables\n",
      "    plot_data = PlotData(data, variables)\n",
      "  File \"/Users/rmitta/opt/anaconda3/envs/truskawka/lib/python3.10/site-packages/seaborn/_core/data.py\", line 58, in __init__\n",
      "    frame, names, ids = self._assign_variables(data, variables)\n",
      "  File \"/Users/rmitta/opt/anaconda3/envs/truskawka/lib/python3.10/site-packages/seaborn/_core/data.py\", line 232, in _assign_variables\n",
      "    raise ValueError(err)\n",
      "ValueError: Could not interpret value `population_2020` for `x`. An entry with this name does not appear in `data`.\n",
      "2025-07-23 18:44:41.272 Uncaught app execution\n",
      "Traceback (most recent call last):\n",
      "  File \"/Users/rmitta/opt/anaconda3/envs/truskawka/lib/python3.10/site-packages/streamlit/runtime/scriptrunner/exec_code.py\", line 128, in exec_func_with_error_handling\n",
      "    result = func()\n",
      "  File \"/Users/rmitta/opt/anaconda3/envs/truskawka/lib/python3.10/site-packages/streamlit/runtime/scriptrunner/script_runner.py\", line 667, in code_to_exec\n",
      "    _mpa_v1(self._main_script_path)\n",
      "  File \"/Users/rmitta/opt/anaconda3/envs/truskawka/lib/python3.10/site-packages/streamlit/runtime/scriptrunner/script_runner.py\", line 165, in _mpa_v1\n",
      "    page.run()\n",
      "  File \"/Users/rmitta/opt/anaconda3/envs/truskawka/lib/python3.10/site-packages/streamlit/navigation/page.py\", line 300, in run\n",
      "    exec(code, module.__dict__)  # noqa: S102\n",
      "  File \"/Users/rmitta/Documents/GitHub/cities/pages/6 ðŸ†• Kaya Identity.py\", line 78, in <module>\n",
      "    sns.scatterplot(data=df_merge,x=x, y=y, s=100, alpha=0.7)\n",
      "NameError: name 'df_merge' is not defined\n",
      "2025-07-23 18:47:20.034 Uncaught app execution\n",
      "Traceback (most recent call last):\n",
      "  File \"/Users/rmitta/opt/anaconda3/envs/truskawka/lib/python3.10/site-packages/streamlit/runtime/scriptrunner/exec_code.py\", line 128, in exec_func_with_error_handling\n",
      "    result = func()\n",
      "  File \"/Users/rmitta/opt/anaconda3/envs/truskawka/lib/python3.10/site-packages/streamlit/runtime/scriptrunner/script_runner.py\", line 667, in code_to_exec\n",
      "    _mpa_v1(self._main_script_path)\n",
      "  File \"/Users/rmitta/opt/anaconda3/envs/truskawka/lib/python3.10/site-packages/streamlit/runtime/scriptrunner/script_runner.py\", line 165, in _mpa_v1\n",
      "    page.run()\n",
      "  File \"/Users/rmitta/opt/anaconda3/envs/truskawka/lib/python3.10/site-packages/streamlit/navigation/page.py\", line 296, in run\n",
      "    code = ctx.pages_manager.get_page_script_byte_code(str(self._page))\n",
      "  File \"/Users/rmitta/opt/anaconda3/envs/truskawka/lib/python3.10/site-packages/streamlit/runtime/pages_manager.py\", line 160, in get_page_script_byte_code\n",
      "    return self._script_cache.get_bytecode(script_path)\n",
      "  File \"/Users/rmitta/opt/anaconda3/envs/truskawka/lib/python3.10/site-packages/streamlit/runtime/scriptrunner/script_cache.py\", line 72, in get_bytecode\n",
      "    filebody = magic.add_magic(filebody, script_path)\n",
      "  File \"/Users/rmitta/opt/anaconda3/envs/truskawka/lib/python3.10/site-packages/streamlit/runtime/scriptrunner/magic.py\", line 45, in add_magic\n",
      "    tree = ast.parse(code, script_path, \"exec\")\n",
      "  File \"/Users/rmitta/opt/anaconda3/envs/truskawka/lib/python3.10/ast.py\", line 50, in parse\n",
      "    return compile(source, filename, mode, flags,\n",
      "  File \"/Users/rmitta/Documents/GitHub/cities/pages/6 ðŸ†• Kaya Identity.py\", line 78\n",
      "    \"Major roads (1,2,3 functional classes), Minor roads (4,5,6 functional classes).\")\n",
      "                                                                                     ^\n",
      "SyntaxError: unmatched ')'\n",
      "2025-07-23 18:47:21.463 Uncaught app execution\n",
      "Traceback (most recent call last):\n",
      "  File \"/Users/rmitta/opt/anaconda3/envs/truskawka/lib/python3.10/site-packages/streamlit/runtime/scriptrunner/exec_code.py\", line 128, in exec_func_with_error_handling\n",
      "    result = func()\n",
      "  File \"/Users/rmitta/opt/anaconda3/envs/truskawka/lib/python3.10/site-packages/streamlit/runtime/scriptrunner/script_runner.py\", line 667, in code_to_exec\n",
      "    _mpa_v1(self._main_script_path)\n",
      "  File \"/Users/rmitta/opt/anaconda3/envs/truskawka/lib/python3.10/site-packages/streamlit/runtime/scriptrunner/script_runner.py\", line 165, in _mpa_v1\n",
      "    page.run()\n",
      "  File \"/Users/rmitta/opt/anaconda3/envs/truskawka/lib/python3.10/site-packages/streamlit/navigation/page.py\", line 296, in run\n",
      "    code = ctx.pages_manager.get_page_script_byte_code(str(self._page))\n",
      "  File \"/Users/rmitta/opt/anaconda3/envs/truskawka/lib/python3.10/site-packages/streamlit/runtime/pages_manager.py\", line 160, in get_page_script_byte_code\n",
      "    return self._script_cache.get_bytecode(script_path)\n",
      "  File \"/Users/rmitta/opt/anaconda3/envs/truskawka/lib/python3.10/site-packages/streamlit/runtime/scriptrunner/script_cache.py\", line 72, in get_bytecode\n",
      "    filebody = magic.add_magic(filebody, script_path)\n",
      "  File \"/Users/rmitta/opt/anaconda3/envs/truskawka/lib/python3.10/site-packages/streamlit/runtime/scriptrunner/magic.py\", line 45, in add_magic\n",
      "    tree = ast.parse(code, script_path, \"exec\")\n",
      "  File \"/Users/rmitta/opt/anaconda3/envs/truskawka/lib/python3.10/ast.py\", line 50, in parse\n",
      "    return compile(source, filename, mode, flags,\n",
      "  File \"/Users/rmitta/Documents/GitHub/cities/pages/6 ðŸ†• Kaya Identity.py\", line 78\n",
      "    \"Major roads (1,2,3 functional classes), Minor roads (4,5,6 functional classes).\")\n",
      "                                                                                     ^\n",
      "SyntaxError: unmatched ')'\n",
      "2025-07-23 18:48:04.808 Uncaught app execution\n",
      "Traceback (most recent call last):\n",
      "  File \"/Users/rmitta/opt/anaconda3/envs/truskawka/lib/python3.10/site-packages/streamlit/runtime/scriptrunner/exec_code.py\", line 128, in exec_func_with_error_handling\n",
      "    result = func()\n",
      "  File \"/Users/rmitta/opt/anaconda3/envs/truskawka/lib/python3.10/site-packages/streamlit/runtime/scriptrunner/script_runner.py\", line 667, in code_to_exec\n",
      "    _mpa_v1(self._main_script_path)\n",
      "  File \"/Users/rmitta/opt/anaconda3/envs/truskawka/lib/python3.10/site-packages/streamlit/runtime/scriptrunner/script_runner.py\", line 165, in _mpa_v1\n",
      "    page.run()\n",
      "  File \"/Users/rmitta/opt/anaconda3/envs/truskawka/lib/python3.10/site-packages/streamlit/navigation/page.py\", line 300, in run\n",
      "    exec(code, module.__dict__)  # noqa: S102\n",
      "  File \"/Users/rmitta/Documents/GitHub/cities/pages/6 ðŸ†• Kaya Identity.py\", line 71, in <module>\n",
      "    st.markdown(\"### Cumulative COâ‚‚ Contribution by Functional Class\")\n",
      "AttributeError: module 'streamlit' has no attribute 'ma'\n"
     ]
    }
   ],
   "source": [
    "!streamlit run Data_Overview.py"
   ]
  },
  {
   "cell_type": "code",
   "execution_count": null,
   "metadata": {},
   "outputs": [],
   "source": []
  }
 ],
 "metadata": {
  "kernelspec": {
   "display_name": "truskawka",
   "language": "python",
   "name": "python3"
  },
  "language_info": {
   "codemirror_mode": {
    "name": "ipython",
    "version": 3
   },
   "file_extension": ".py",
   "mimetype": "text/x-python",
   "name": "python",
   "nbconvert_exporter": "python",
   "pygments_lexer": "ipython3",
   "version": "3.10.18"
  },
  "orig_nbformat": 4
 },
 "nbformat": 4,
 "nbformat_minor": 2
}
