{
 "cells": [
  {
   "cell_type": "code",
   "execution_count": 4,
   "metadata": {},
   "outputs": [
    {
     "name": "stdout",
     "output_type": "stream",
     "text": [
      "2024-05-20 13:13:17.702 INFO    numexpr.utils: Note: NumExpr detected 10 cores but \"NUMEXPR_MAX_THREADS\" not set, so enforcing safe limit of 8.\n",
      "2024-05-20 13:13:17.702 INFO    numexpr.utils: NumExpr defaulting to 8 threads.\n",
      "\u001b[0m\n",
      "\u001b[34m\u001b[1m  You can now view your Streamlit app in your browser.\u001b[0m\n",
      "\u001b[0m\n",
      "\u001b[34m  Local URL: \u001b[0m\u001b[1mhttp://localhost:8501\u001b[0m\n",
      "\u001b[34m  Network URL: \u001b[0m\u001b[1mhttp://192.168.1.10:8501\u001b[0m\n",
      "\u001b[0m\n",
      "2024-05-20 13:13:21.332 Uncaught app exception\n",
      "Traceback (most recent call last):\n",
      "  File \"/Users/rmitta/opt/anaconda3/envs/zerotwo/lib/python3.10/site-packages/streamlit/runtime/scriptrunner/script_runner.py\", line 556, in _run_script\n",
      "    exec(code, module.__dict__)\n",
      "  File \"/Users/rmitta/Desktop/work/3. Indian Traffic/streamlit/cities/Data_Overview.py\", line 20, in <module>\n",
      "    from streamlit_folium import st_folium\n",
      "ModuleNotFoundError: No module named 'streamlit_folium'\n",
      "2024-05-20 13:13:32.383 Uncaught app exception\n",
      "Traceback (most recent call last):\n",
      "  File \"/Users/rmitta/opt/anaconda3/envs/zerotwo/lib/python3.10/site-packages/streamlit/runtime/scriptrunner/script_runner.py\", line 556, in _run_script\n",
      "    exec(code, module.__dict__)\n",
      "  File \"/Users/rmitta/Desktop/work/3. Indian Traffic/streamlit/cities/Data_Overview.py\", line 20, in <module>\n",
      "    from streamlit_folium import st_folium\n",
      "ModuleNotFoundError: No module named 'streamlit_folium'\n",
      "/Users/rmitta/opt/anaconda3/envs/zerotwo/lib/python3.10/site-packages/cartopy/io/__init__.py:241: DownloadWarning: Downloading: https://naturalearth.s3.amazonaws.com/50m_physical/ne_50m_land.zip\n",
      "  warnings.warn(f'Downloading: {url}', DownloadWarning)\n",
      "/Users/rmitta/opt/anaconda3/envs/zerotwo/lib/python3.10/site-packages/cartopy/io/__init__.py:241: DownloadWarning: Downloading: https://naturalearth.s3.amazonaws.com/50m_physical/ne_50m_ocean.zip\n",
      "  warnings.warn(f'Downloading: {url}', DownloadWarning)\n",
      "/Users/rmitta/opt/anaconda3/envs/zerotwo/lib/python3.10/site-packages/cartopy/io/__init__.py:241: DownloadWarning: Downloading: https://naturalearth.s3.amazonaws.com/50m_physical/ne_50m_coastline.zip\n",
      "  warnings.warn(f'Downloading: {url}', DownloadWarning)\n",
      "/Users/rmitta/opt/anaconda3/envs/zerotwo/lib/python3.10/site-packages/cartopy/io/__init__.py:241: DownloadWarning: Downloading: https://naturalearth.s3.amazonaws.com/50m_cultural/ne_50m_admin_0_boundary_lines_land.zip\n",
      "  warnings.warn(f'Downloading: {url}', DownloadWarning)\n",
      "/Users/rmitta/opt/anaconda3/envs/zerotwo/lib/python3.10/site-packages/cartopy/io/__init__.py:241: DownloadWarning: Downloading: https://naturalearth.s3.amazonaws.com/50m_physical/ne_50m_lakes.zip\n",
      "  warnings.warn(f'Downloading: {url}', DownloadWarning)\n",
      "/Users/rmitta/opt/anaconda3/envs/zerotwo/lib/python3.10/site-packages/cartopy/io/__init__.py:241: DownloadWarning: Downloading: https://naturalearth.s3.amazonaws.com/50m_physical/ne_50m_rivers_lake_centerlines.zip\n",
      "  warnings.warn(f'Downloading: {url}', DownloadWarning)\n",
      "2024-05-20 13:16:44.249 Uncaught app exception\n",
      "Traceback (most recent call last):\n",
      "  File \"/Users/rmitta/opt/anaconda3/envs/zerotwo/lib/python3.10/site-packages/streamlit/runtime/scriptrunner/script_runner.py\", line 556, in _run_script\n",
      "    exec(code, module.__dict__)\n",
      "  File \"/Users/rmitta/Desktop/work/3. Indian Traffic/streamlit/cities/Data_Overview.py\", line 20, in <module>\n",
      "    from streamlit_folium import st_folium\n",
      "ModuleNotFoundError: No module named 'streamlit_folium'\n",
      "2024-05-20 13:16:46.471 Uncaught app exception\n",
      "Traceback (most recent call last):\n",
      "  File \"/Users/rmitta/opt/anaconda3/envs/zerotwo/lib/python3.10/site-packages/streamlit/runtime/scriptrunner/script_runner.py\", line 556, in _run_script\n",
      "    exec(code, module.__dict__)\n",
      "  File \"/Users/rmitta/Desktop/work/3. Indian Traffic/streamlit/cities/Data_Overview.py\", line 18, in <module>\n",
      "    from streamlit_folium import st_folium\n",
      "ModuleNotFoundError: No module named 'streamlit_folium'\n",
      "2024-05-20 13:16:48.709 Uncaught app exception\n",
      "Traceback (most recent call last):\n",
      "  File \"/Users/rmitta/opt/anaconda3/envs/zerotwo/lib/python3.10/site-packages/streamlit/runtime/scriptrunner/script_runner.py\", line 556, in _run_script\n",
      "    exec(code, module.__dict__)\n",
      "  File \"/Users/rmitta/Desktop/work/3. Indian Traffic/streamlit/cities/Data_Overview.py\", line 18, in <module>\n",
      "    from streamlit_folium import st_folium\n",
      "ModuleNotFoundError: No module named 'streamlit_folium'\n",
      "2024-05-20 13:19:50.507 Uncaught app exception\n",
      "Traceback (most recent call last):\n",
      "  File \"/Users/rmitta/opt/anaconda3/envs/zerotwo/lib/python3.10/site-packages/streamlit/runtime/scriptrunner/script_runner.py\", line 556, in _run_script\n",
      "    premature_stop = True\n",
      "  File \"/Users/rmitta/Desktop/work/3. Indian Traffic/streamlit/cities/Data_Overview.py\", line 29, in <module>\n",
      "    coordinates = get_city_coordinates(city)\n",
      "  File \"/Users/rmitta/Desktop/work/3. Indian Traffic/streamlit/cities/Data_Overview.py\", line 22, in get_city_coordinates\n",
      "    location = geolocator.geocode(city_name)\n",
      "NameError: name 'geolocator' is not defined\n",
      "2024-05-20 13:20:04.797 Uncaught app exception\n",
      "Traceback (most recent call last):\n",
      "  File \"/Users/rmitta/opt/anaconda3/envs/zerotwo/lib/python3.10/site-packages/streamlit/runtime/scriptrunner/script_runner.py\", line 556, in _run_script\n",
      "    premature_stop = True\n",
      "  File \"/Users/rmitta/Desktop/work/3. Indian Traffic/streamlit/cities/Data_Overview.py\", line 30, in <module>\n",
      "    coordinates = get_city_coordinates(city)\n",
      "  File \"/Users/rmitta/Desktop/work/3. Indian Traffic/streamlit/cities/Data_Overview.py\", line 23, in get_city_coordinates\n",
      "    location = geolocator.geocode(city_name)\n",
      "NameError: name 'geolocator' is not defined\n",
      "2024-05-20 13:20:07.037 Uncaught app exception\n",
      "Traceback (most recent call last):\n",
      "  File \"/Users/rmitta/opt/anaconda3/envs/zerotwo/lib/python3.10/site-packages/streamlit/runtime/scriptrunner/script_runner.py\", line 556, in _run_script\n",
      "    premature_stop = True\n",
      "  File \"/Users/rmitta/Desktop/work/3. Indian Traffic/streamlit/cities/Data_Overview.py\", line 30, in <module>\n",
      "    coordinates = get_city_coordinates(city)\n",
      "  File \"/Users/rmitta/Desktop/work/3. Indian Traffic/streamlit/cities/Data_Overview.py\", line 23, in get_city_coordinates\n",
      "    location = geolocator.geocode(city_name)\n",
      "NameError: name 'geolocator' is not defined\n",
      "2024-05-20 13:20:09.999 Uncaught app exception\n",
      "Traceback (most recent call last):\n",
      "  File \"/Users/rmitta/opt/anaconda3/envs/zerotwo/lib/python3.10/site-packages/streamlit/runtime/scriptrunner/script_runner.py\", line 556, in _run_script\n",
      "    premature_stop = True\n",
      "  File \"/Users/rmitta/Desktop/work/3. Indian Traffic/streamlit/cities/Data_Overview.py\", line 28, in <module>\n",
      "    coordinates = get_city_coordinates(city)\n",
      "  File \"/Users/rmitta/Desktop/work/3. Indian Traffic/streamlit/cities/Data_Overview.py\", line 21, in get_city_coordinates\n",
      "    location = geolocator.geocode(city_name)\n",
      "NameError: name 'geolocator' is not defined\n",
      "2024-05-20 13:20:12.289 Uncaught app exception\n",
      "Traceback (most recent call last):\n",
      "  File \"/Users/rmitta/opt/anaconda3/envs/zerotwo/lib/python3.10/site-packages/streamlit/runtime/scriptrunner/script_runner.py\", line 556, in _run_script\n",
      "    premature_stop = True\n",
      "  File \"/Users/rmitta/Desktop/work/3. Indian Traffic/streamlit/cities/Data_Overview.py\", line 27, in <module>\n",
      "    coordinates = get_city_coordinates(city)\n",
      "  File \"/Users/rmitta/Desktop/work/3. Indian Traffic/streamlit/cities/Data_Overview.py\", line 20, in get_city_coordinates\n",
      "    location = geolocator.geocode(city_name)\n",
      "NameError: name 'geolocator' is not defined\n",
      "2024-05-20 13:20:17.585 Uncaught app exception\n",
      "Traceback (most recent call last):\n",
      "  File \"/Users/rmitta/opt/anaconda3/envs/zerotwo/lib/python3.10/site-packages/streamlit/runtime/scriptrunner/script_runner.py\", line 556, in _run_script\n",
      "    premature_stop = True\n",
      "  File \"/Users/rmitta/Desktop/work/3. Indian Traffic/streamlit/cities/Data_Overview.py\", line 27, in <module>\n",
      "    coordinates = get_city_coordinates(city)\n",
      "  File \"/Users/rmitta/Desktop/work/3. Indian Traffic/streamlit/cities/Data_Overview.py\", line 20, in get_city_coordinates\n",
      "    location = geolocator.geocode(city_name)\n",
      "NameError: name 'geolocator' is not defined\n",
      "2024-05-20 13:20:49.848 Uncaught app exception\n",
      "Traceback (most recent call last):\n",
      "  File \"/Users/rmitta/opt/anaconda3/envs/zerotwo/lib/python3.10/site-packages/streamlit/runtime/scriptrunner/script_runner.py\", line 556, in _run_script\n",
      "    premature_stop = True\n",
      "  File \"/Users/rmitta/Desktop/work/3. Indian Traffic/streamlit/cities/Data_Overview.py\", line 27, in <module>\n",
      "    coordinates = get_city_coordinates(city)\n",
      "  File \"/Users/rmitta/Desktop/work/3. Indian Traffic/streamlit/cities/Data_Overview.py\", line 20, in get_city_coordinates\n",
      "    location = geolocator.geocode(city_name)\n",
      "NameError: name 'geolocator' is not defined\n",
      "2024-05-20 13:23:18.117 Retrying (Retry(total=1, connect=None, read=None, redirect=None, status=None)) after connection broken by 'ReadTimeoutError(\"HTTPSConnectionPool(host='nominatim.openstreetmap.org', port=443): Read timed out. (read timeout=1)\")': /search?q=Kochi&format=json&limit=1\n",
      "2024-05-20 13:23:22.892 Retrying (Retry(total=1, connect=None, read=None, redirect=None, status=None)) after connection broken by 'ReadTimeoutError(\"HTTPSConnectionPool(host='nominatim.openstreetmap.org', port=443): Read timed out. (read timeout=1)\")': /search?q=Gangtok&format=json&limit=1\n",
      "2024-05-20 13:23:23.937 Retrying (Retry(total=0, connect=None, read=None, redirect=None, status=None)) after connection broken by 'ReadTimeoutError(\"HTTPSConnectionPool(host='nominatim.openstreetmap.org', port=443): Read timed out. (read timeout=1)\")': /search?q=Gangtok&format=json&limit=1\n",
      "2024-05-20 13:23:59.878 Uncaught app exception\n",
      "Traceback (most recent call last):\n",
      "  File \"/Users/rmitta/opt/anaconda3/envs/zerotwo/lib/python3.10/site-packages/streamlit/runtime/scriptrunner/script_runner.py\", line 556, in _run_script\n",
      "    premature_stop = True\n",
      "  File \"/Users/rmitta/Desktop/work/3. Indian Traffic/streamlit/cities/Data_Overview.py\", line 26, in <module>\n",
      "    coordinates = get_city_coordinates(city)\n",
      "  File \"/Users/rmitta/Desktop/work/3. Indian Traffic/streamlit/cities/Data_Overview.py\", line 19, in get_city_coordinates\n",
      "    location = geolocator.geocode(city_name)\n",
      "NameError: name 'geolocator' is not defined\n",
      "2024-05-20 13:24:03.911 Retrying (Retry(total=1, connect=None, read=None, redirect=None, status=None)) after connection broken by 'ReadTimeoutError(\"HTTPSConnectionPool(host='nominatim.openstreetmap.org', port=443): Read timed out. (read timeout=1)\")': /search?q=Gangtok&format=json&limit=1\n"
     ]
    }
   ],
   "source": [
    "!streamlit run Data_Overview.py"
   ]
  }
 ],
 "metadata": {
  "kernelspec": {
   "display_name": "Python 3.10.6 ('zerotwo')",
   "language": "python",
   "name": "python3"
  },
  "language_info": {
   "codemirror_mode": {
    "name": "ipython",
    "version": 3
   },
   "file_extension": ".py",
   "mimetype": "text/x-python",
   "name": "python",
   "nbconvert_exporter": "python",
   "pygments_lexer": "ipython3",
   "version": "3.10.6"
  },
  "orig_nbformat": 4,
  "vscode": {
   "interpreter": {
    "hash": "9bfb04bc2ddf749979761a4feac0c518cf5ca390f648d1feb34c0cf89edffd23"
   }
  }
 },
 "nbformat": 4,
 "nbformat_minor": 2
}
