{
 "cells": [
  {
   "cell_type": "code",
   "execution_count": 1,
   "metadata": {},
   "outputs": [
    {
     "name": "stdout",
     "output_type": "stream",
     "text": [
      "2024-05-06 15:34:28.308 INFO    numexpr.utils: Note: NumExpr detected 10 cores but \"NUMEXPR_MAX_THREADS\" not set, so enforcing safe limit of 8.\n",
      "2024-05-06 15:34:28.308 INFO    numexpr.utils: NumExpr defaulting to 8 threads.\n",
      "\u001b[0m\n",
      "\u001b[34m\u001b[1m  You can now view your Streamlit app in your browser.\u001b[0m\n",
      "\u001b[0m\n",
      "\u001b[34m  Local URL: \u001b[0m\u001b[1mhttp://localhost:8501\u001b[0m\n",
      "\u001b[34m  Network URL: \u001b[0m\u001b[1mhttp://192.168.1.10:8501\u001b[0m\n",
      "\u001b[0m\n",
      "2024-05-06 15:34:32.691 Uncaught app exception\n",
      "Traceback (most recent call last):\n",
      "  File \"/Users/rmitta/opt/anaconda3/envs/zerotwo/lib/python3.10/site-packages/streamlit/runtime/scriptrunner/script_runner.py\", line 556, in _run_script\n",
      "    exec(code, module.__dict__)\n",
      "  File \"/Users/rmitta/Desktop/work/3. Indian Traffic/streamlit/cities/Data_Overview.py\", line 21, in <module>\n",
      "    st.image('data/region/data.png')\n",
      "  File \"/Users/rmitta/opt/anaconda3/envs/zerotwo/lib/python3.10/site-packages/streamlit/elements/image.py\", line 138, in image\n",
      "    marshall_images(\n",
      "  File \"/Users/rmitta/opt/anaconda3/envs/zerotwo/lib/python3.10/site-packages/streamlit/elements/image.py\", line 423, in marshall_images\n",
      "    proto_img.url = image_to_url(\n",
      "  File \"/Users/rmitta/opt/anaconda3/envs/zerotwo/lib/python3.10/site-packages/streamlit/elements/image.py\", line 339, in image_to_url\n",
      "    with open(image, \"rb\") as f:\n",
      "FileNotFoundError: [Errno 2] No such file or directory: 'data/region/data.png'\n",
      "2024-05-06 16:33:38.219 Uncaught app exception\n",
      "Traceback (most recent call last):\n",
      "  File \"/Users/rmitta/opt/anaconda3/envs/zerotwo/lib/python3.10/site-packages/streamlit/runtime/scriptrunner/script_runner.py\", line 556, in _run_script\n",
      "    exec(code, module.__dict__)\n",
      "  File \"/Users/rmitta/Desktop/work/3. Indian Traffic/streamlit/cities/Data_Overview.py\", line 18, in <module>\n",
      "    st.image()\n",
      "TypeError: ImageMixin.image() missing 1 required positional argument: 'image'\n",
      "2024-05-06 16:33:41.921 Uncaught app exception\n",
      "Traceback (most recent call last):\n",
      "  File \"/Users/rmitta/opt/anaconda3/envs/zerotwo/lib/python3.10/site-packages/streamlit/runtime/scriptrunner/script_runner.py\", line 556, in _run_script\n",
      "    exec(code, module.__dict__)\n",
      "  File \"/Users/rmitta/Desktop/work/3. Indian Traffic/streamlit/cities/Data_Overview.py\", line 18, in <module>\n",
      "    st.image('data/')\n",
      "  File \"/Users/rmitta/opt/anaconda3/envs/zerotwo/lib/python3.10/site-packages/streamlit/elements/image.py\", line 138, in image\n",
      "    marshall_images(\n",
      "  File \"/Users/rmitta/opt/anaconda3/envs/zerotwo/lib/python3.10/site-packages/streamlit/elements/image.py\", line 423, in marshall_images\n",
      "    proto_img.url = image_to_url(\n",
      "  File \"/Users/rmitta/opt/anaconda3/envs/zerotwo/lib/python3.10/site-packages/streamlit/elements/image.py\", line 339, in image_to_url\n",
      "    with open(image, \"rb\") as f:\n",
      "IsADirectoryError: [Errno 21] Is a directory: 'data/'\n",
      "2024-05-06 16:33:44.862 Uncaught app exception\n",
      "Traceback (most recent call last):\n",
      "  File \"/Users/rmitta/opt/anaconda3/envs/zerotwo/lib/python3.10/site-packages/streamlit/runtime/scriptrunner/script_runner.py\", line 556, in _run_script\n",
      "    exec(code, module.__dict__)\n",
      "  File \"/Users/rmitta/Desktop/work/3. Indian Traffic/streamlit/cities/Data_Overview.py\", line 18, in <module>\n",
      "    st.image('data/{}')\n",
      "  File \"/Users/rmitta/opt/anaconda3/envs/zerotwo/lib/python3.10/site-packages/streamlit/elements/image.py\", line 138, in image\n",
      "    marshall_images(\n",
      "  File \"/Users/rmitta/opt/anaconda3/envs/zerotwo/lib/python3.10/site-packages/streamlit/elements/image.py\", line 423, in marshall_images\n",
      "    proto_img.url = image_to_url(\n",
      "  File \"/Users/rmitta/opt/anaconda3/envs/zerotwo/lib/python3.10/site-packages/streamlit/elements/image.py\", line 339, in image_to_url\n",
      "    with open(image, \"rb\") as f:\n",
      "FileNotFoundError: [Errno 2] No such file or directory: 'data/{}'\n",
      "2024-05-06 16:33:50.421 Uncaught app exception\n",
      "Traceback (most recent call last):\n",
      "  File \"/Users/rmitta/opt/anaconda3/envs/zerotwo/lib/python3.10/site-packages/streamlit/runtime/scriptrunner/script_runner.py\", line 556, in _run_script\n",
      "    exec(code, module.__dict__)\n",
      "  File \"/Users/rmitta/Desktop/work/3. Indian Traffic/streamlit/cities/Data_Overview.py\", line 18, in <module>\n",
      "    st.image('data/{}')\n",
      "  File \"/Users/rmitta/opt/anaconda3/envs/zerotwo/lib/python3.10/site-packages/streamlit/elements/image.py\", line 138, in image\n",
      "    marshall_images(\n",
      "  File \"/Users/rmitta/opt/anaconda3/envs/zerotwo/lib/python3.10/site-packages/streamlit/elements/image.py\", line 423, in marshall_images\n",
      "    proto_img.url = image_to_url(\n",
      "  File \"/Users/rmitta/opt/anaconda3/envs/zerotwo/lib/python3.10/site-packages/streamlit/elements/image.py\", line 339, in image_to_url\n",
      "    with open(image, \"rb\") as f:\n",
      "FileNotFoundError: [Errno 2] No such file or directory: 'data/{}'\n",
      "2024-05-06 16:33:53.826 Uncaught app exception\n",
      "Traceback (most recent call last):\n",
      "  File \"/Users/rmitta/opt/anaconda3/envs/zerotwo/lib/python3.10/site-packages/streamlit/runtime/scriptrunner/script_runner.py\", line 556, in _run_script\n",
      "    exec(code, module.__dict__)\n",
      "  File \"/Users/rmitta/Desktop/work/3. Indian Traffic/streamlit/cities/Data_Overview.py\", line 18, in <module>\n",
      "    st.image(f'data/{city}')\n",
      "  File \"/Users/rmitta/opt/anaconda3/envs/zerotwo/lib/python3.10/site-packages/streamlit/elements/image.py\", line 138, in image\n",
      "    marshall_images(\n",
      "  File \"/Users/rmitta/opt/anaconda3/envs/zerotwo/lib/python3.10/site-packages/streamlit/elements/image.py\", line 423, in marshall_images\n",
      "    proto_img.url = image_to_url(\n",
      "  File \"/Users/rmitta/opt/anaconda3/envs/zerotwo/lib/python3.10/site-packages/streamlit/elements/image.py\", line 339, in image_to_url\n",
      "    with open(image, \"rb\") as f:\n",
      "IsADirectoryError: [Errno 21] Is a directory: 'data/Kohima'\n",
      "2024-05-06 16:33:55.347 Uncaught app exception\n",
      "Traceback (most recent call last):\n",
      "  File \"/Users/rmitta/opt/anaconda3/envs/zerotwo/lib/python3.10/site-packages/streamlit/runtime/scriptrunner/script_runner.py\", line 556, in _run_script\n",
      "    exec(code, module.__dict__)\n",
      "  File \"/Users/rmitta/Desktop/work/3. Indian Traffic/streamlit/cities/Data_Overview.py\", line 18, in <module>\n",
      "    st.image(f'data/{city}/')\n",
      "  File \"/Users/rmitta/opt/anaconda3/envs/zerotwo/lib/python3.10/site-packages/streamlit/elements/image.py\", line 138, in image\n",
      "    marshall_images(\n",
      "  File \"/Users/rmitta/opt/anaconda3/envs/zerotwo/lib/python3.10/site-packages/streamlit/elements/image.py\", line 423, in marshall_images\n",
      "    proto_img.url = image_to_url(\n",
      "  File \"/Users/rmitta/opt/anaconda3/envs/zerotwo/lib/python3.10/site-packages/streamlit/elements/image.py\", line 339, in image_to_url\n",
      "    with open(image, \"rb\") as f:\n",
      "IsADirectoryError: [Errno 21] Is a directory: 'data/Kohima/'\n",
      "2024-05-06 16:33:56.922 Uncaught app exception\n",
      "Traceback (most recent call last):\n",
      "  File \"/Users/rmitta/opt/anaconda3/envs/zerotwo/lib/python3.10/site-packages/streamlit/runtime/scriptrunner/script_runner.py\", line 556, in _run_script\n",
      "    exec(code, module.__dict__)\n",
      "  File \"/Users/rmitta/Desktop/work/3. Indian Traffic/streamlit/cities/Data_Overview.py\", line 18, in <module>\n",
      "    st.image(f'data/{city}/1')\n",
      "  File \"/Users/rmitta/opt/anaconda3/envs/zerotwo/lib/python3.10/site-packages/streamlit/elements/image.py\", line 138, in image\n",
      "    marshall_images(\n",
      "  File \"/Users/rmitta/opt/anaconda3/envs/zerotwo/lib/python3.10/site-packages/streamlit/elements/image.py\", line 423, in marshall_images\n",
      "    proto_img.url = image_to_url(\n",
      "  File \"/Users/rmitta/opt/anaconda3/envs/zerotwo/lib/python3.10/site-packages/streamlit/elements/image.py\", line 339, in image_to_url\n",
      "    with open(image, \"rb\") as f:\n",
      "FileNotFoundError: [Errno 2] No such file or directory: 'data/Kohima/1'\n",
      "2024-05-06 17:24:36.945 Uncaught app exception\n",
      "Traceback (most recent call last):\n",
      "  File \"/Users/rmitta/opt/anaconda3/envs/zerotwo/lib/python3.10/site-packages/streamlit/runtime/scriptrunner/script_runner.py\", line 556, in _run_script\n",
      "    exec(code, module.__dict__)\n",
      "  File \"/Users/rmitta/Desktop/work/3. Indian Traffic/streamlit/cities/Data_Overview.py\", line 20, in <module>\n",
      "    st.image(f'data/{city}/3.png')\n",
      "  File \"/Users/rmitta/opt/anaconda3/envs/zerotwo/lib/python3.10/site-packages/streamlit/elements/image.py\", line 138, in image\n",
      "    marshall_images(\n",
      "  File \"/Users/rmitta/opt/anaconda3/envs/zerotwo/lib/python3.10/site-packages/streamlit/elements/image.py\", line 423, in marshall_images\n",
      "    proto_img.url = image_to_url(\n",
      "  File \"/Users/rmitta/opt/anaconda3/envs/zerotwo/lib/python3.10/site-packages/streamlit/elements/image.py\", line 339, in image_to_url\n",
      "    with open(image, \"rb\") as f:\n",
      "FileNotFoundError: [Errno 2] No such file or directory: 'data/Kohima/3.png'\n",
      "2024-05-06 17:24:40.330 Uncaught app exception\n",
      "Traceback (most recent call last):\n",
      "  File \"/Users/rmitta/opt/anaconda3/envs/zerotwo/lib/python3.10/site-packages/streamlit/runtime/scriptrunner/script_runner.py\", line 556, in _run_script\n",
      "    exec(code, module.__dict__)\n",
      "  File \"/Users/rmitta/Desktop/work/3. Indian Traffic/streamlit/cities/Data_Overview.py\", line 20, in <module>\n",
      "    st.image(f'data/{city}/3.png')\n",
      "  File \"/Users/rmitta/opt/anaconda3/envs/zerotwo/lib/python3.10/site-packages/streamlit/elements/image.py\", line 138, in image\n",
      "    marshall_images(\n",
      "  File \"/Users/rmitta/opt/anaconda3/envs/zerotwo/lib/python3.10/site-packages/streamlit/elements/image.py\", line 423, in marshall_images\n",
      "    proto_img.url = image_to_url(\n",
      "  File \"/Users/rmitta/opt/anaconda3/envs/zerotwo/lib/python3.10/site-packages/streamlit/elements/image.py\", line 339, in image_to_url\n",
      "    with open(image, \"rb\") as f:\n",
      "FileNotFoundError: [Errno 2] No such file or directory: 'data/Kohima/3.png'\n",
      "2024-05-06 17:25:08.970 Uncaught app exception\n",
      "Traceback (most recent call last):\n",
      "  File \"/Users/rmitta/opt/anaconda3/envs/zerotwo/lib/python3.10/site-packages/streamlit/runtime/scriptrunner/script_runner.py\", line 556, in _run_script\n",
      "    exec(code, module.__dict__)\n",
      "  File \"/Users/rmitta/Desktop/work/3. Indian Traffic/streamlit/cities/Data_Overview.py\", line 20, in <module>\n",
      "    st.image(f'data/{city}/3.png')\n",
      "  File \"/Users/rmitta/opt/anaconda3/envs/zerotwo/lib/python3.10/site-packages/streamlit/elements/image.py\", line 138, in image\n",
      "    marshall_images(\n",
      "  File \"/Users/rmitta/opt/anaconda3/envs/zerotwo/lib/python3.10/site-packages/streamlit/elements/image.py\", line 423, in marshall_images\n",
      "    proto_img.url = image_to_url(\n",
      "  File \"/Users/rmitta/opt/anaconda3/envs/zerotwo/lib/python3.10/site-packages/streamlit/elements/image.py\", line 339, in image_to_url\n",
      "    with open(image, \"rb\") as f:\n",
      "FileNotFoundError: [Errno 2] No such file or directory: 'data/Kohima/3.png'\n",
      "2024-05-06 17:25:15.561 Uncaught app exception\n",
      "Traceback (most recent call last):\n",
      "  File \"/Users/rmitta/opt/anaconda3/envs/zerotwo/lib/python3.10/site-packages/streamlit/runtime/scriptrunner/script_runner.py\", line 556, in _run_script\n",
      "    exec(code, module.__dict__)\n",
      "  File \"/Users/rmitta/Desktop/work/3. Indian Traffic/streamlit/cities/Data_Overview.py\", line 20, in <module>\n",
      "    st.image(f'data/{city}/.png')\n",
      "  File \"/Users/rmitta/opt/anaconda3/envs/zerotwo/lib/python3.10/site-packages/streamlit/elements/image.py\", line 138, in image\n",
      "    marshall_images(\n",
      "  File \"/Users/rmitta/opt/anaconda3/envs/zerotwo/lib/python3.10/site-packages/streamlit/elements/image.py\", line 423, in marshall_images\n",
      "    proto_img.url = image_to_url(\n",
      "  File \"/Users/rmitta/opt/anaconda3/envs/zerotwo/lib/python3.10/site-packages/streamlit/elements/image.py\", line 339, in image_to_url\n",
      "    with open(image, \"rb\") as f:\n",
      "FileNotFoundError: [Errno 2] No such file or directory: 'data/Kohima/.png'\n",
      "2024-05-06 17:25:26.230 Uncaught app exception\n",
      "Traceback (most recent call last):\n",
      "  File \"/Users/rmitta/opt/anaconda3/envs/zerotwo/lib/python3.10/site-packages/streamlit/runtime/scriptrunner/script_runner.py\", line 556, in _run_script\n",
      "    exec(code, module.__dict__)\n",
      "  File \"/Users/rmitta/Desktop/work/3. Indian Traffic/streamlit/cities/Data_Overview.py\", line 20, in <module>\n",
      "    st.image(f'data/{city}/comparison.png')\n",
      "  File \"/Users/rmitta/opt/anaconda3/envs/zerotwo/lib/python3.10/site-packages/streamlit/elements/image.py\", line 138, in image\n",
      "    marshall_images(\n",
      "  File \"/Users/rmitta/opt/anaconda3/envs/zerotwo/lib/python3.10/site-packages/streamlit/elements/image.py\", line 423, in marshall_images\n",
      "    proto_img.url = image_to_url(\n",
      "  File \"/Users/rmitta/opt/anaconda3/envs/zerotwo/lib/python3.10/site-packages/streamlit/elements/image.py\", line 339, in image_to_url\n",
      "    with open(image, \"rb\") as f:\n",
      "FileNotFoundError: [Errno 2] No such file or directory: 'data/Kohima/comparison.png'\n",
      "2024-05-06 17:25:28.947 Uncaught app exception\n",
      "Traceback (most recent call last):\n",
      "  File \"/Users/rmitta/opt/anaconda3/envs/zerotwo/lib/python3.10/site-packages/streamlit/runtime/scriptrunner/script_runner.py\", line 556, in _run_script\n",
      "    exec(code, module.__dict__)\n",
      "  File \"/Users/rmitta/Desktop/work/3. Indian Traffic/streamlit/cities/Data_Overview.py\", line 29, in <module>\n",
      "    st.image(f'data/{city}/3.png')\n",
      "  File \"/Users/rmitta/opt/anaconda3/envs/zerotwo/lib/python3.10/site-packages/streamlit/elements/image.py\", line 138, in image\n",
      "    marshall_images(\n",
      "  File \"/Users/rmitta/opt/anaconda3/envs/zerotwo/lib/python3.10/site-packages/streamlit/elements/image.py\", line 423, in marshall_images\n",
      "    proto_img.url = image_to_url(\n",
      "  File \"/Users/rmitta/opt/anaconda3/envs/zerotwo/lib/python3.10/site-packages/streamlit/elements/image.py\", line 339, in image_to_url\n",
      "    with open(image, \"rb\") as f:\n",
      "FileNotFoundError: [Errno 2] No such file or directory: 'data/Kohima/3.png'\n",
      "2024-05-06 17:25:36.957 Uncaught app exception\n",
      "Traceback (most recent call last):\n",
      "  File \"/Users/rmitta/opt/anaconda3/envs/zerotwo/lib/python3.10/site-packages/streamlit/runtime/scriptrunner/script_runner.py\", line 556, in _run_script\n",
      "    exec(code, module.__dict__)\n",
      "  File \"/Users/rmitta/Desktop/work/3. Indian Traffic/streamlit/cities/Data_Overview.py\", line 30, in <module>\n",
      "    more_details = st.checkbox('Show Individual Plots')\n",
      "  File \"/Users/rmitta/opt/anaconda3/envs/zerotwo/lib/python3.10/site-packages/streamlit/elements/checkbox.py\", line 92, in checkbox\n",
      "    return self._checkbox(\n",
      "  File \"/Users/rmitta/opt/anaconda3/envs/zerotwo/lib/python3.10/site-packages/streamlit/elements/checkbox.py\", line 133, in _checkbox\n",
      "    checkbox_state = register_widget(\n",
      "  File \"/Users/rmitta/opt/anaconda3/envs/zerotwo/lib/python3.10/site-packages/streamlit/runtime/state/widgets.py\", line 211, in register_widget\n",
      "    raise DuplicateWidgetID(\n",
      "streamlit.errors.DuplicateWidgetID: There are multiple identical `st.checkbox` widgets with the\n",
      "same generated key.\n",
      "\n",
      "When a widget is created, it's assigned an internal key based on\n",
      "its structure. Multiple widgets with an identical structure will\n",
      "result in the same internal key, which causes this error.\n",
      "\n",
      "To fix this error, please pass a unique `key` argument to\n",
      "`st.checkbox`.\n",
      "2024-05-06 17:25:57.009 Uncaught app exception\n",
      "Traceback (most recent call last):\n",
      "  File \"/Users/rmitta/opt/anaconda3/envs/zerotwo/lib/python3.10/site-packages/streamlit/runtime/scriptrunner/script_runner.py\", line 556, in _run_script\n",
      "    exec(code, module.__dict__)\n",
      "  File \"/Users/rmitta/Desktop/work/3. Indian Traffic/streamlit/cities/Data_Overview.py\", line 30, in <module>\n",
      "    more_details = st.checkbox('Show Individual Plots')\n",
      "  File \"/Users/rmitta/opt/anaconda3/envs/zerotwo/lib/python3.10/site-packages/streamlit/elements/checkbox.py\", line 92, in checkbox\n",
      "    return self._checkbox(\n",
      "  File \"/Users/rmitta/opt/anaconda3/envs/zerotwo/lib/python3.10/site-packages/streamlit/elements/checkbox.py\", line 133, in _checkbox\n",
      "    checkbox_state = register_widget(\n",
      "  File \"/Users/rmitta/opt/anaconda3/envs/zerotwo/lib/python3.10/site-packages/streamlit/runtime/state/widgets.py\", line 211, in register_widget\n",
      "    raise DuplicateWidgetID(\n",
      "streamlit.errors.DuplicateWidgetID: There are multiple identical `st.checkbox` widgets with the\n",
      "same generated key.\n",
      "\n",
      "When a widget is created, it's assigned an internal key based on\n",
      "its structure. Multiple widgets with an identical structure will\n",
      "result in the same internal key, which causes this error.\n",
      "\n",
      "To fix this error, please pass a unique `key` argument to\n",
      "`st.checkbox`.\n",
      "2024-05-06 17:26:00.720 Uncaught app exception\n",
      "Traceback (most recent call last):\n",
      "  File \"/Users/rmitta/opt/anaconda3/envs/zerotwo/lib/python3.10/site-packages/streamlit/runtime/scriptrunner/script_runner.py\", line 556, in _run_script\n",
      "    exec(code, module.__dict__)\n",
      "  File \"/Users/rmitta/Desktop/work/3. Indian Traffic/streamlit/cities/Data_Overview.py\", line 30, in <module>\n",
      "    more_details = st.checkbox('Show Individual Plots')\n",
      "  File \"/Users/rmitta/opt/anaconda3/envs/zerotwo/lib/python3.10/site-packages/streamlit/elements/checkbox.py\", line 92, in checkbox\n",
      "    return self._checkbox(\n",
      "  File \"/Users/rmitta/opt/anaconda3/envs/zerotwo/lib/python3.10/site-packages/streamlit/elements/checkbox.py\", line 133, in _checkbox\n",
      "    checkbox_state = register_widget(\n",
      "  File \"/Users/rmitta/opt/anaconda3/envs/zerotwo/lib/python3.10/site-packages/streamlit/runtime/state/widgets.py\", line 211, in register_widget\n",
      "    raise DuplicateWidgetID(\n",
      "streamlit.errors.DuplicateWidgetID: There are multiple identical `st.checkbox` widgets with the\n",
      "same generated key.\n",
      "\n",
      "When a widget is created, it's assigned an internal key based on\n",
      "its structure. Multiple widgets with an identical structure will\n",
      "result in the same internal key, which causes this error.\n",
      "\n",
      "To fix this error, please pass a unique `key` argument to\n",
      "`st.checkbox`.\n",
      "2024-05-06 17:26:11.722 Uncaught app exception\n",
      "Traceback (most recent call last):\n",
      "  File \"/Users/rmitta/opt/anaconda3/envs/zerotwo/lib/python3.10/site-packages/streamlit/runtime/scriptrunner/script_runner.py\", line 556, in _run_script\n",
      "    exec(code, module.__dict__)\n",
      "  File \"/Users/rmitta/Desktop/work/3. Indian Traffic/streamlit/cities/Data_Overview.py\", line 30, in <module>\n",
      "    more_details = st.checkbox('Show Individual Plots')\n",
      "  File \"/Users/rmitta/opt/anaconda3/envs/zerotwo/lib/python3.10/site-packages/streamlit/elements/checkbox.py\", line 92, in checkbox\n",
      "    return self._checkbox(\n",
      "  File \"/Users/rmitta/opt/anaconda3/envs/zerotwo/lib/python3.10/site-packages/streamlit/elements/checkbox.py\", line 133, in _checkbox\n",
      "    checkbox_state = register_widget(\n",
      "  File \"/Users/rmitta/opt/anaconda3/envs/zerotwo/lib/python3.10/site-packages/streamlit/runtime/state/widgets.py\", line 211, in register_widget\n",
      "    raise DuplicateWidgetID(\n",
      "streamlit.errors.DuplicateWidgetID: There are multiple identical `st.checkbox` widgets with the\n",
      "same generated key.\n",
      "\n",
      "When a widget is created, it's assigned an internal key based on\n",
      "its structure. Multiple widgets with an identical structure will\n",
      "result in the same internal key, which causes this error.\n",
      "\n",
      "To fix this error, please pass a unique `key` argument to\n",
      "`st.checkbox`.\n",
      "2024-05-06 17:26:14.205 Uncaught app exception\n",
      "Traceback (most recent call last):\n",
      "  File \"/Users/rmitta/opt/anaconda3/envs/zerotwo/lib/python3.10/site-packages/streamlit/runtime/scriptrunner/script_runner.py\", line 556, in _run_script\n",
      "    exec(code, module.__dict__)\n",
      "  File \"/Users/rmitta/Desktop/work/3. Indian Traffic/streamlit/cities/Data_Overview.py\", line 30, in <module>\n",
      "    more_details = st.checkbox('Show Individual Plots')\n",
      "  File \"/Users/rmitta/opt/anaconda3/envs/zerotwo/lib/python3.10/site-packages/streamlit/elements/checkbox.py\", line 92, in checkbox\n",
      "    return self._checkbox(\n",
      "  File \"/Users/rmitta/opt/anaconda3/envs/zerotwo/lib/python3.10/site-packages/streamlit/elements/checkbox.py\", line 133, in _checkbox\n",
      "    checkbox_state = register_widget(\n",
      "  File \"/Users/rmitta/opt/anaconda3/envs/zerotwo/lib/python3.10/site-packages/streamlit/runtime/state/widgets.py\", line 211, in register_widget\n",
      "    raise DuplicateWidgetID(\n",
      "streamlit.errors.DuplicateWidgetID: There are multiple identical `st.checkbox` widgets with the\n",
      "same generated key.\n",
      "\n",
      "When a widget is created, it's assigned an internal key based on\n",
      "its structure. Multiple widgets with an identical structure will\n",
      "result in the same internal key, which causes this error.\n",
      "\n",
      "To fix this error, please pass a unique `key` argument to\n",
      "`st.checkbox`.\n",
      "2024-05-06 17:26:23.641 Uncaught app exception\n",
      "Traceback (most recent call last):\n",
      "  File \"/Users/rmitta/opt/anaconda3/envs/zerotwo/lib/python3.10/site-packages/streamlit/runtime/scriptrunner/script_runner.py\", line 556, in _run_script\n",
      "    exec(code, module.__dict__)\n",
      "  File \"/Users/rmitta/Desktop/work/3. Indian Traffic/streamlit/cities/Data_Overview.py\", line 30, in <module>\n",
      "    more_details = st.checkbox('Show Individual Plots')\n",
      "  File \"/Users/rmitta/opt/anaconda3/envs/zerotwo/lib/python3.10/site-packages/streamlit/elements/checkbox.py\", line 92, in checkbox\n",
      "    return self._checkbox(\n",
      "  File \"/Users/rmitta/opt/anaconda3/envs/zerotwo/lib/python3.10/site-packages/streamlit/elements/checkbox.py\", line 133, in _checkbox\n",
      "    checkbox_state = register_widget(\n",
      "  File \"/Users/rmitta/opt/anaconda3/envs/zerotwo/lib/python3.10/site-packages/streamlit/runtime/state/widgets.py\", line 211, in register_widget\n",
      "    raise DuplicateWidgetID(\n",
      "streamlit.errors.DuplicateWidgetID: There are multiple identical `st.checkbox` widgets with the\n",
      "same generated key.\n",
      "\n",
      "When a widget is created, it's assigned an internal key based on\n",
      "its structure. Multiple widgets with an identical structure will\n",
      "result in the same internal key, which causes this error.\n",
      "\n",
      "To fix this error, please pass a unique `key` argument to\n",
      "`st.checkbox`.\n",
      "2024-05-06 17:26:27.548 Uncaught app exception\n",
      "Traceback (most recent call last):\n",
      "  File \"/Users/rmitta/opt/anaconda3/envs/zerotwo/lib/python3.10/site-packages/streamlit/runtime/scriptrunner/script_runner.py\", line 556, in _run_script\n",
      "    exec(code, module.__dict__)\n",
      "  File \"/Users/rmitta/Desktop/work/3. Indian Traffic/streamlit/cities/Data_Overview.py\", line 30, in <module>\n",
      "    more_details = st.checkbox('Show Individual Plots')\n",
      "  File \"/Users/rmitta/opt/anaconda3/envs/zerotwo/lib/python3.10/site-packages/streamlit/elements/checkbox.py\", line 92, in checkbox\n",
      "    return self._checkbox(\n",
      "  File \"/Users/rmitta/opt/anaconda3/envs/zerotwo/lib/python3.10/site-packages/streamlit/elements/checkbox.py\", line 133, in _checkbox\n",
      "    checkbox_state = register_widget(\n",
      "  File \"/Users/rmitta/opt/anaconda3/envs/zerotwo/lib/python3.10/site-packages/streamlit/runtime/state/widgets.py\", line 211, in register_widget\n",
      "    raise DuplicateWidgetID(\n",
      "streamlit.errors.DuplicateWidgetID: There are multiple identical `st.checkbox` widgets with the\n",
      "same generated key.\n",
      "\n",
      "When a widget is created, it's assigned an internal key based on\n",
      "its structure. Multiple widgets with an identical structure will\n",
      "result in the same internal key, which causes this error.\n",
      "\n",
      "To fix this error, please pass a unique `key` argument to\n",
      "`st.checkbox`.\n",
      "2024-05-06 17:26:36.252 Uncaught app exception\n",
      "Traceback (most recent call last):\n",
      "  File \"/Users/rmitta/opt/anaconda3/envs/zerotwo/lib/python3.10/site-packages/streamlit/runtime/scriptrunner/script_runner.py\", line 556, in _run_script\n",
      "    exec(code, module.__dict__)\n",
      "  File \"/Users/rmitta/Desktop/work/3. Indian Traffic/streamlit/cities/Data_Overview.py\", line 30, in <module>\n",
      "    more_details2 = st.checkbox('Show Individual Plots')\n",
      "  File \"/Users/rmitta/opt/anaconda3/envs/zerotwo/lib/python3.10/site-packages/streamlit/elements/checkbox.py\", line 92, in checkbox\n",
      "    return self._checkbox(\n",
      "  File \"/Users/rmitta/opt/anaconda3/envs/zerotwo/lib/python3.10/site-packages/streamlit/elements/checkbox.py\", line 133, in _checkbox\n",
      "    checkbox_state = register_widget(\n",
      "  File \"/Users/rmitta/opt/anaconda3/envs/zerotwo/lib/python3.10/site-packages/streamlit/runtime/state/widgets.py\", line 211, in register_widget\n",
      "    raise DuplicateWidgetID(\n",
      "streamlit.errors.DuplicateWidgetID: There are multiple identical `st.checkbox` widgets with the\n",
      "same generated key.\n",
      "\n",
      "When a widget is created, it's assigned an internal key based on\n",
      "its structure. Multiple widgets with an identical structure will\n",
      "result in the same internal key, which causes this error.\n",
      "\n",
      "To fix this error, please pass a unique `key` argument to\n",
      "`st.checkbox`.\n",
      "2024-05-06 17:26:37.541 Uncaught app exception\n",
      "Traceback (most recent call last):\n",
      "  File \"/Users/rmitta/opt/anaconda3/envs/zerotwo/lib/python3.10/site-packages/streamlit/runtime/scriptrunner/script_runner.py\", line 556, in _run_script\n",
      "    exec(code, module.__dict__)\n",
      "  File \"/Users/rmitta/Desktop/work/3. Indian Traffic/streamlit/cities/Data_Overview.py\", line 30, in <module>\n",
      "    more_details2 = st.checkbox('Show Individual Plots')\n",
      "  File \"/Users/rmitta/opt/anaconda3/envs/zerotwo/lib/python3.10/site-packages/streamlit/elements/checkbox.py\", line 92, in checkbox\n",
      "    return self._checkbox(\n",
      "  File \"/Users/rmitta/opt/anaconda3/envs/zerotwo/lib/python3.10/site-packages/streamlit/elements/checkbox.py\", line 133, in _checkbox\n",
      "    checkbox_state = register_widget(\n",
      "  File \"/Users/rmitta/opt/anaconda3/envs/zerotwo/lib/python3.10/site-packages/streamlit/runtime/state/widgets.py\", line 211, in register_widget\n",
      "    raise DuplicateWidgetID(\n",
      "streamlit.errors.DuplicateWidgetID: There are multiple identical `st.checkbox` widgets with the\n",
      "same generated key.\n",
      "\n",
      "When a widget is created, it's assigned an internal key based on\n",
      "its structure. Multiple widgets with an identical structure will\n",
      "result in the same internal key, which causes this error.\n",
      "\n",
      "To fix this error, please pass a unique `key` argument to\n",
      "`st.checkbox`.\n",
      "2024-05-06 17:27:47.406 Uncaught app exception\n",
      "Traceback (most recent call last):\n",
      "  File \"/Users/rmitta/opt/anaconda3/envs/zerotwo/lib/python3.10/site-packages/streamlit/runtime/scriptrunner/script_runner.py\", line 556, in _run_script\n",
      "    exec(code, module.__dict__)\n",
      "  File \"/Users/rmitta/Desktop/work/3. Indian Traffic/streamlit/cities/Data_Overview.py\", line 30, in <module>\n",
      "    more_details2 = st.checkbox('Show Individual Plots')\n",
      "  File \"/Users/rmitta/opt/anaconda3/envs/zerotwo/lib/python3.10/site-packages/streamlit/elements/checkbox.py\", line 92, in checkbox\n",
      "    return self._checkbox(\n",
      "  File \"/Users/rmitta/opt/anaconda3/envs/zerotwo/lib/python3.10/site-packages/streamlit/elements/checkbox.py\", line 133, in _checkbox\n",
      "    checkbox_state = register_widget(\n",
      "  File \"/Users/rmitta/opt/anaconda3/envs/zerotwo/lib/python3.10/site-packages/streamlit/runtime/state/widgets.py\", line 211, in register_widget\n",
      "    raise DuplicateWidgetID(\n",
      "streamlit.errors.DuplicateWidgetID: There are multiple identical `st.checkbox` widgets with the\n",
      "same generated key.\n",
      "\n",
      "When a widget is created, it's assigned an internal key based on\n",
      "its structure. Multiple widgets with an identical structure will\n",
      "result in the same internal key, which causes this error.\n",
      "\n",
      "To fix this error, please pass a unique `key` argument to\n",
      "`st.checkbox`.\n",
      "2024-05-06 17:27:50.398 Uncaught app exception\n",
      "Traceback (most recent call last):\n",
      "  File \"/Users/rmitta/opt/anaconda3/envs/zerotwo/lib/python3.10/site-packages/streamlit/runtime/scriptrunner/script_runner.py\", line 556, in _run_script\n",
      "    exec(code, module.__dict__)\n",
      "  File \"/Users/rmitta/Desktop/work/3. Indian Traffic/streamlit/cities/Data_Overview.py\", line 30, in <module>\n",
      "    more_details2 = st.checkbox('Show Individual Plots')\n",
      "  File \"/Users/rmitta/opt/anaconda3/envs/zerotwo/lib/python3.10/site-packages/streamlit/elements/checkbox.py\", line 92, in checkbox\n",
      "    return self._checkbox(\n",
      "  File \"/Users/rmitta/opt/anaconda3/envs/zerotwo/lib/python3.10/site-packages/streamlit/elements/checkbox.py\", line 133, in _checkbox\n",
      "    checkbox_state = register_widget(\n",
      "  File \"/Users/rmitta/opt/anaconda3/envs/zerotwo/lib/python3.10/site-packages/streamlit/runtime/state/widgets.py\", line 211, in register_widget\n",
      "    raise DuplicateWidgetID(\n",
      "streamlit.errors.DuplicateWidgetID: There are multiple identical `st.checkbox` widgets with the\n",
      "same generated key.\n",
      "\n",
      "When a widget is created, it's assigned an internal key based on\n",
      "its structure. Multiple widgets with an identical structure will\n",
      "result in the same internal key, which causes this error.\n",
      "\n",
      "To fix this error, please pass a unique `key` argument to\n",
      "`st.checkbox`.\n",
      "2024-05-06 17:29:00.629 Uncaught app exception\n",
      "Traceback (most recent call last):\n",
      "  File \"/Users/rmitta/opt/anaconda3/envs/zerotwo/lib/python3.10/site-packages/streamlit/runtime/scriptrunner/script_runner.py\", line 556, in _run_script\n",
      "    exec(code, module.__dict__)\n",
      "  File \"/Users/rmitta/Desktop/work/3. Indian Traffic/streamlit/cities/Data_Overview.py\", line 30, in <module>\n",
      "    more_details2 = st.checkbox('Show Individual Plots',key='count')\n",
      "  File \"/Users/rmitta/opt/anaconda3/envs/zerotwo/lib/python3.10/site-packages/streamlit/elements/checkbox.py\", line 92, in checkbox\n",
      "    return self._checkbox(\n",
      "  File \"/Users/rmitta/opt/anaconda3/envs/zerotwo/lib/python3.10/site-packages/streamlit/elements/checkbox.py\", line 133, in _checkbox\n",
      "    checkbox_state = register_widget(\n",
      "  File \"/Users/rmitta/opt/anaconda3/envs/zerotwo/lib/python3.10/site-packages/streamlit/runtime/state/widgets.py\", line 199, in register_widget\n",
      "    raise DuplicateWidgetID(\n",
      "streamlit.errors.DuplicateWidgetID: There are multiple identical `st.checkbox` widgets with\n",
      "`key='count'`.\n",
      "\n",
      "To fix this, please make sure that the `key` argument is unique for\n",
      "each `st.checkbox` you create.\n",
      "2024-05-06 17:29:06.868 Uncaught app exception\n",
      "Traceback (most recent call last):\n",
      "  File \"/Users/rmitta/opt/anaconda3/envs/zerotwo/lib/python3.10/site-packages/streamlit/runtime/scriptrunner/script_runner.py\", line 556, in _run_script\n",
      "    exec(code, module.__dict__)\n",
      "  File \"/Users/rmitta/Desktop/work/3. Indian Traffic/streamlit/cities/Data_Overview.py\", line 32, in <module>\n",
      "    st.image(f'data/{city}/passengerspeed.png')\n",
      "  File \"/Users/rmitta/opt/anaconda3/envs/zerotwo/lib/python3.10/site-packages/streamlit/elements/image.py\", line 138, in image\n",
      "    marshall_images(\n",
      "  File \"/Users/rmitta/opt/anaconda3/envs/zerotwo/lib/python3.10/site-packages/streamlit/elements/image.py\", line 423, in marshall_images\n",
      "    proto_img.url = image_to_url(\n",
      "  File \"/Users/rmitta/opt/anaconda3/envs/zerotwo/lib/python3.10/site-packages/streamlit/elements/image.py\", line 339, in image_to_url\n",
      "    with open(image, \"rb\") as f:\n",
      "FileNotFoundError: [Errno 2] No such file or directory: 'data/Kohima/passengerspeed.png'\n",
      "2024-05-06 17:29:32.902 Uncaught app exception\n",
      "Traceback (most recent call last):\n",
      "  File \"/Users/rmitta/opt/anaconda3/envs/zerotwo/lib/python3.10/site-packages/streamlit/runtime/scriptrunner/script_runner.py\", line 556, in _run_script\n",
      "    exec(code, module.__dict__)\n",
      "  File \"/Users/rmitta/Desktop/work/3. Indian Traffic/streamlit/cities/Data_Overview.py\", line 33, in <module>\n",
      "    st.image(f'data/{city}/truckspeed.png')\n",
      "  File \"/Users/rmitta/opt/anaconda3/envs/zerotwo/lib/python3.10/site-packages/streamlit/elements/image.py\", line 138, in image\n",
      "    marshall_images(\n",
      "  File \"/Users/rmitta/opt/anaconda3/envs/zerotwo/lib/python3.10/site-packages/streamlit/elements/image.py\", line 423, in marshall_images\n",
      "    proto_img.url = image_to_url(\n",
      "  File \"/Users/rmitta/opt/anaconda3/envs/zerotwo/lib/python3.10/site-packages/streamlit/elements/image.py\", line 339, in image_to_url\n",
      "    with open(image, \"rb\") as f:\n",
      "FileNotFoundError: [Errno 2] No such file or directory: 'data/Kohima/truckspeed.png'\n"
     ]
    }
   ],
   "source": [
    "!streamlit run Data_Overview.py"
   ]
  },
  {
   "cell_type": "code",
   "execution_count": 11,
   "metadata": {},
   "outputs": [],
   "source": [
    "import geopandas as gpd\n",
    "import numpy as np\n",
    "import pandas as pd\n",
    "import xarray as xr\n",
    "import shapely\n",
    "import pickle\n",
    "import pandas as pd\n",
    "import numpy as np\n",
    "import pickle\n",
    "import tqdm\n",
    "import pandas as pd\n",
    "import string\n",
    "import numpy as np\n",
    "import geopandas as gpd\n",
    "import pickle\n",
    "import datetime\n",
    "import pwlf\n",
    "import scipy\n",
    "import sklearn"
   ]
  },
  {
   "cell_type": "code",
   "execution_count": 16,
   "metadata": {},
   "outputs": [],
   "source": [
    "\n",
    "# Dictionary to store imported libraries and their versions\n",
    "imported_libraries = {\n",
    "    'geopandas': gpd.__version__,\n",
    "    'numpy': np.__version__,\n",
    "    'pandas': pd.__version__,\n",
    "    'xarray': xr.__version__,\n",
    "    'shapely': shapely.__version__,\n",
    "    'tqdm': tqdm.__version__,\n",
    "    'pwlf': pwlf.__version__,\n",
    "    'scipy': scipy.__version__,\n",
    "    'sklearn': sklearn.__version__  \n",
    "}\n",
    "\n",
    "# Write the imported libraries and versions to requirements.txt\n",
    "with open('requirements.txt', 'w') as f:\n",
    "    for library, version in imported_libraries.items():\n",
    "        f.write(f\"{library}=={version}\\n\")\n"
   ]
  }
 ],
 "metadata": {
  "kernelspec": {
   "display_name": "Python 3.10.6 ('zerotwo')",
   "language": "python",
   "name": "python3"
  },
  "language_info": {
   "codemirror_mode": {
    "name": "ipython",
    "version": 3
   },
   "file_extension": ".py",
   "mimetype": "text/x-python",
   "name": "python",
   "nbconvert_exporter": "python",
   "pygments_lexer": "ipython3",
   "version": "3.10.6"
  },
  "orig_nbformat": 4,
  "vscode": {
   "interpreter": {
    "hash": "9bfb04bc2ddf749979761a4feac0c518cf5ca390f648d1feb34c0cf89edffd23"
   }
  }
 },
 "nbformat": 4,
 "nbformat_minor": 2
}
